Workbook

Sheet 0501
A1: 内容 | B1: 内容类型 | C1: 内容发布时间 | D1: 本期阅读量 | E1: 本期收益 | F1: 累计阅读量 | G1: 累计收益 | J1: 新增浏览 | K1: 新增收益
A2: 请问在不破坏树的情况下怎么把树皮腐蚀下来一点，不让大树压到房子? | B2: 回答 | C2: 45777 | D2: 92 | E2: 226 | F2: 92 | G2: 226 | H2: =E2/D2 -> 2.4565217 | I2: =G2/F2 -> 2.4565217 | J2: 92 | K2: 226 | L2: =IFERROR(K2/J2,) -> 2.4565217
A3: 香椿的功效与作用是什么呢？ | B3: 回答 | C3: 45777 | D3: 61 | E3: 165 | F3: 61 | G3: 165 | H3: =E3/D3 -> 2.704918 | I3: =G3/F3 -> 2.704918 | J3: 61 | K3: 165 | L3: =IFERROR(K3/J3,) -> 2.704918
A4: 人一天到底要吃多少，才不会太多也不会太少？ | B4: 回答 | C4: 45776 | D4: 350 | E4: 368 | F4: 350 | G4: 368 | H4: =E4/D4 -> 1.0514286 | I4: =G4/F4 -> 1.0514286 | J4: 232 | K4: 155 | L4: =IFERROR(K4/J4,) -> 0.66810345
A5: 同样的时间，为什么早上煮的菜晚上可以吃，但晚上煮的菜第二天早上就叫隔夜菜，吃了就不利于健康呢？ | B5: 回答 | C5: 45775 | D5: 200 | E5: 277 | F5: 200 | G5: 277 | H5: =E5/D5 -> 1.385 | I5: =G5/F5 -> 1.385 | J5: 56 | K5: 60 | L5: =IFERROR(K5/J5,) -> 1.0714286
A6: 能否告诉我这花团锦簇的是什么树？ | B6: 回答 | C6: 45775 | D6: 133 | E6: 304 | F6: 133 | G6: 304 | H6: =E6/D6 -> 2.2857143 | I6: =G6/F6 -> 2.2857143 | J6: 14 | K6: 28 | L6: =IFERROR(K6/J6,) -> 2
A7: 医生说少油少盐，不可抗拒的原因一直在吃食堂，是不是少吃点多喝汤就达到上述要求？ | B7: 回答 | C7: 45774 | D7: 136 | E7: 216 | F7: 136 | G7: 216 | H7: =E7/D7 -> 1.5882353 | I7: =G7/F7 -> 1.5882353 | J7: 7 | K7: 8 | L7: =IFERROR(K7/J7,) -> 1.1428571
A8: 有人说一周吃四个鸡蛋就够了，有人说每天一个鸡蛋最好，到底哪种说法更合适？ | B8: 回答 | C8: 45774 | D8: 372 | E8: 363 | F8: 372 | G8: 363 | H8: =E8/D8 -> 0.97580645 | I8: =G8/F8 -> 0.97580645 | J8: 22 | K8: 64 | L8: =IFERROR(K8/J8,) -> 2.9090909
A9: 这是什么品种的花卉？ | B9: 回答 | C9: 45773 | D9: 134 | E9: 190 | F9: 134 | G9: 190 | H9: =E9/D9 -> 1.4179104 | I9: =G9/F9 -> 1.4179104 | J9: 22 | K9: 8 | L9: =IFERROR(K9/J9,) -> 0.36363636
A10: 酸菜炖大骨头好吃的做法有哪些？ | B10: 回答 | C10: 45773 | D10: 215 | E10: 241 | F10: 215 | G10: 241 | H10: =E10/D10 -> 1.1209302 | I10: =G10/F10 -> 1.1209302 | J10: 5 | K10: 6 | L10: =IFERROR(K10/J10,) -> 1.2
A11: 两杯水中，一杯其中加盐鸡蛋会怎么样？ | B11: 回答 | C11: 45772 | D11: 124 | E11: 462 | F11: 124 | G11: 462 | H11: =E11/D11 -> 3.7258065 | I11: =G11/F11 -> 3.7258065 | J11: 26 | K11: 122 | L11: =IFERROR(K11/J11,) -> 4.6923077 | M11: 0430顶99,23,26,2,1
A12: 煎鱼总粘锅破皮是物理问题还是技术问题？家庭厨房如何彻底解决？ | B12: 回答 | C12: 45771 | D12: 184 | E12: 177 | F12: 184 | G12: 177 | H12: =E12/D12 -> 0.96195652 | I12: =G12/F12 -> 0.96195652 | J12: 7 | K12: 6 | L12: =IFERROR(K12/J12,) -> 0.85714286
A13: 蝴蝶兰花茎为啥这么粗壮？ | B13: 回答 | C13: 45771 | D13: 156 | E13: 121 | F13: 156 | G13: 121 | H13: =E13/D13 -> 0.77564103 | I13: =G13/F13 -> 0.77564103 | J13: 19 | K13: 0 | L13: =IFERROR(K13/J13,) -> 0
A14: 血压高适合吃哪些食物？ | B14: 回答 | C14: 45770 | D14: 147 | E14: 493 | F14: 210 | G14: 685 | H14: =E14/D14 -> 3.3537415 | I14: =G14/F14 -> 3.2619048 | J14: 14 | K14: 4 | L14: =IFERROR(K14/J14,) -> 0.28571429 | M14: 0426顶98,26,40,3,1
A15: 小时候都是吃猪油，为什么不知道从什么时候就没出现在餐桌上了? | B15: 回答 | C15: 45770 | D15: 628 | E15: 161 | F15: 794 | G15: 397 | H15: =E15/D15 -> 0.25636943 | I15: =G15/F15 -> 0.5 | J15: 5 | K15: 0 | L15: =IFERROR(K15/J15,) -> 0
A16: 这个长在植物上白色东西是甚么？会不会影响植物生长？ | B16: 回答 | C16: 45769 | D16: 44 | E16: 77 | F16: 141 | G16: 418 | H16: =E16/D16 -> 1.75 | I16: =G16/F16 -> 2.964539 | J16: 0 | K16: 0 | L16: =IFERROR(K16/J16,) -> 0
A17: 你能不能找到一个比较简单的数学问题，但是deepseek却得不到正确结果？ | B17: 回答 | C17: 45769 | D17: 217 | E17: 14 | F17: 546 | G17: 334 | H17: =E17/D17 -> 0.064516129 | I17: =G17/F17 -> 0.61172161 | J17: 16 | K17: 0 | L17: =IFERROR(K17/J17,) -> 0
A18: 同样的电饭煲煮饭，用不同的大米煮，加的水是一样的吗？ | B18: 回答 | C18: 45768 | D18: 32 | E18: 12 | F18: 215 | G18: 603 | H18: =E18/D18 -> 0.375 | I18: =G18/F18 -> 2.8046512 | J18: 0 | K18: 0 | L18: =IFERROR(K18/J18,) -> 0
A19: 怎么分辨桃花樱桃李子树花梨花呢？ | B19: 回答 | C19: 45768 | D19: 47 | E19: 114 | F19: 142 | G19: 469 | H19: =E19/D19 -> 2.4255319 | I19: =G19/F19 -> 3.3028169 | J19: 0 | K19: 0 | L19: =IFERROR(K19/J19,) -> 0 | M19: 0424顶96,23,30,2,4
A20: 有认识这是什么植物长出来的苗吗？ | B20: 回答 | C20: 45767 | D20: 321 | E20: 43 | F20: 1107 | G20: 290 | H20: =E20/D20 -> 0.13395639 | I20: =G20/F20 -> 0.26196929 | J20: 24 | K20: 0 | L20: =IFERROR(K20/J20,) -> 0
A21: 问一个数学问题，可能有99%的人都答错：6个鸡蛋，打碎了两个，煮了两个，吃了两个，还剩几个？ | B21: 回答 | C21: 45766 | D21: 192 | E21: 50 | F21: 849 | G21: 583 | H21: =E21/D21 -> 0.26041667 | I21: =G21/F21 -> 0.68669022 | J21: 12 | K21: 0 | L21: =IFERROR(K21/J21,) -> 0
A22: 排骨放高压锅炖要几分钟? | B22: 回答 | C22: 45766 | D22: 33 | E22: 12 | F22: 225 | G22: 285 | H22: =E22/D22 -> 0.36363636 | I22: =G22/F22 -> 1.2666667 | J22: 2 | K22: 0 | L22: =IFERROR(K22/J22,) -> 0
A23: 为啥大中火煸油 没等油煸出来就糊了? | B23: 回答 | C23: 45765 | D23: 31 | E23: 31 | F23: 401 | G23: 452 | H23: =E23/D23 -> 1 | I23: =G23/F23 -> 1.127182 | J23: 0 | K23: 0 | L23: =IFERROR(K23/J23,) -> 0
A24: 鸡头跟鸡屁股都去哪儿了？？？ | B24: 回答 | C24: 45765 | D24: 12 | E24: 32 | F24: 137 | G24: 816 | H24: =E24/D24 -> 2.6666667 | I24: =G24/F24 -> 5.9562044 | J24: 0 | K24: 0 | L24: =IFERROR(K24/J24,) -> 0 | M24: 0420顶42，13，43，3
A25: 一盘饺子姐姐吃剩7个妹妹吃剩9个两人都吃差4个饺子有几个? | B25: 回答 | C25: 45764 | D25: 12 | E25: 7 | F25: 161 | G25: 541 | H25: =E25/D25 -> 0.58333333 | I25: =G25/F25 -> 3.3602484 | J25: 1 | K25: 0 | L25: =IFERROR(K25/J25,) -> 0
A26: 大树被锯掉树冠还能发芽吗？ | B26: 回答 | C26: 45764 | D26: 74 | E26: 7 | F26: 342 | G26: 261 | H26: =E26/D26 -> 0.094594595 | I26: =G26/F26 -> 0.76315789 | J26: 7 | K26: 0 | L26: =IFERROR(K26/J26,) -> 0
A27: 请问怎么能彻底杀死一棵香椿树？ | B27: 回答 | C27: 45763 | D27: 72 | E27: 4 | F27: 648 | G27: 370 | H27: =E27/D27 -> 0.055555556 | I27: =G27/F27 -> 0.57098765 | J27: 0 | K27: 0 | L27: =IFERROR(K27/J27,) -> 0
A28: 少先队员种杨树和柳树共140棵，杨树比柳树多40棵，那么杨树种了多少棵，柳树种了多少棵。? | B28: 回答 | C28: 45763 | D28: 4 | E28: 4 | F28: 130 | G28: 198 | H28: =E28/D28 -> 1 | I28: =G28/F28 -> 1.5230769 | J28: 4 | K28: 4 | L28: =IFERROR(K28/J28,) -> 1 | M28: 0427收益期128，194
A29: 请问在食堂打饭时一两米饭指的是熟重一两还是生重一两? | B29: 回答 | C29: 45762 | D29: 13 | E29: 6 | F29: 595 | G29: 641 | H29: =E29/D29 -> 0.46153846 | I29: =G29/F29 -> 1.0773109 | J29: 13 | K29: 6 | L29: =IFERROR(K29/J29,) -> 0.46153846 | M29: 0428收益期593,635
A30: 做蒸饺时应该怎么和面呢？ | B30: 回答 | C30: 45761 | D30: 37 | E30: 6 | F30: 1054 | G30: 913 | H30: =E30/D30 -> 0.16216216 | I30: =G30/F30 -> 0.86622391 | J30: 37 | K30: 6 | L30: =IFERROR(K30/J30,) -> 0.16216216 | M30: 0426收益期1029,907
A31: 为什么我做的红烧肉总是不够软烂入味，有什么小窍门能让红烧肉达到入口即化的口感呢？ | B31: 回答 | C31: 45757 | D31: 17 | E31: 6 | F31: 624 | G31: 763 | H31: =E31/D31 -> 0.35294118 | I31: =G31/F31 -> 1.2227564 | J31: 0 | K31: 0 | L31: =IFERROR(K31/J31,) -> 0 | M31: 0425收益期613,757
A32: 你们采摘过野外的桑葚么？或者采摘过什么野果野菜？口感怎么样？ | B32: 回答 | C32: 45750 | D32: 9 | E32: 12 | F32: 225 | G32: 542 | H32: =E32/D32 -> 1.3333333 | I32: =G32/F32 -> 2.4088889 | J32: 9 | K32: 12 | L32: =IFERROR(K32/J32,) -> 1.3333333 | M32: 0426收益期222,530
A33: 钟南山呼吁别再「无效节约」，别让剩饭剩菜伤了胃，剩菜剩饭有哪些危害？生活中还有哪些饮食健康易被忽视？ | B33: 回答 | C33: 45748 | D33: 57 | E33: 23 | F33: 224460 | G33: 10593 | H33: =E33/D33 -> 0.40350877 | I33: =G33/F33 -> 0.047193264 | J33: 1 | K33: 0 | L33: =IFERROR(K33/J33,) -> 0 | M33: 0407荐22.3万，784,296,399,48
A34: 谁能提供一个猪肉好吃又简单的做法？ | B34: 回答 | C34: 45743 | D34: 170 | E34: 10 | F34: 4876 | G34: 1986 | H34: =E34/D34 -> 0.058823529 | I34: =G34/F34 -> 0.40730107 | J34: 170 | K34: 10 | L34: =IFERROR(K34/J34,) -> 0.058823529 | M34: 0425收益期4799,1976
A35: 牛肉水煮40分钟后，轻微炒2分钟，吃起来还是很硬很柴，问题出在哪里呢？ | B35: 回答 | C35: 45741 | D35: 127 | E35: 10 | F35: 1193 | G35: 677 | H35: =E35/D35 -> 0.078740157 | I35: =G35/F35 -> 0.56747695 | J35: 13 | K35: 0 | L35: =IFERROR(K35/J35,) -> 0 | M35: 0413收益期928，667
A36: 草莓究竟是哪个季节的果实? | B36: 回答 | C36: 45734 | D36: 41 | E36: 5 | F36: 488 | G36: 670 | H36: =E36/D36 -> 0.12195122 | I36: =G36/F36 -> 1.3729508 | J36: 4 | K36: 0 | L36: =IFERROR(K36/J36,) -> 0 | M36: 0401收益期317,655
A37: 油炸食物很香，哪些蔬菜适合油炸且非常好吃？ | B37: 回答 | C37: 45719 | D37: 8 | E37: 10 | F37: 377 | G37: 657 | H37: =E37/D37 -> 1.25 | I37: =G37/F37 -> 1.7427056 | J37: 8 | K37: 10 | L37: =IFERROR(K37/J37,) -> 1.25 | M37: 0403收益期359,647
A38: 早餐吃什么最好？是牛奶还是面包？ | B38: 回答 | C38: 45713 | D38: 10 | E38: 31 | F38: 225 | G38: 589 | H38: =E38/D38 -> 3.1 | I38: =G38/F38 -> 2.6177778 | J38: 10 | K38: 31 | L38: =IFERROR(K38/J38,) -> 3.1 | M38: 0402收益期203,558
A39: 酥脆剂和泡打粉的区别有哪些？ | B39: 回答 | C39: 45691 | D39: 41 | E39: 5 | F39: 317 | G39: 36 | H39: =E39/D39 -> 0.12195122 | I39: =G39/F39 -> 0.11356467 | J39: 7 | K39: 0 | L39: =IFERROR(K39/J39,) -> 0 | M39: 0216收益期91,31
A40: 鸡蛋放两个月没坏还能吃吗？ | B40: 回答 | C40: 45598 | D40: 65 | E40: 2 | F40: 1262 | G40: 789 | H40: =E40/D40 -> 0.030769231 | I40: =G40/F40 -> 0.6251981 | J40: 8 | K40: 0 | L40: =IFERROR(K40/J40,) -> 0 | M40: 0412收益期1091,787
...

Sheet 0502
A1: 内容 | B1: 内容类型 | C1: 内容发布时间 | D1: 本期阅读量 | E1: 本期收益 | F1: 累计阅读量 | G1: 累计收益 | J1: 新增浏览 | K1: 新增收益
A2: 前几天养了四只小鸡，一只死了。还剩三只鸡，其中的一只鸡又被其它两只小鸡把屁眼那块啄的血琳琳，啥原因？ | B2: 回答 | C2: 45778 | D2: 282 | E2: 126 | F2: 282 | G2: 126 | H2: =E2/D2 -> 0.44680851 | I2: =G2/F2 -> 0.44680851 | J2: =F2-IFERROR(VLOOKUP($A2,'0501'!$A$1:'0501'!G$48,6,FALSE),IFERROR(VLOOKUP($C2,'0501'!$C$1:'0501'!G$48,4,FALSE),F2-D2)) -> 282 | K2: =G2-IFERROR(VLOOKUP($A2,'0501'!$A$1:'0501'!H$44,7,FALSE),IFERROR(VLOOKUP($C2,'0501'!$C$1:'0501'!H$44,5,FALSE),G2-E2)) -> 126 | L2: =IFERROR(K2/J2,) -> 0.44680851
A3: 请问在不破坏树的情况下怎么把树皮腐蚀下来一点，不让大树压到房子? | B3: 回答 | C3: 45777 | D3: 143 | E3: 276 | F3: 143 | G3: 276 | H3: =E3/D3 -> 1.9300699 | I3: =G3/F3 -> 1.9300699 | J3: =F3-IFERROR(VLOOKUP($A3,'0501'!$A$1:'0501'!G$48,6,FALSE),IFERROR(VLOOKUP($C3,'0501'!$C$1:'0501'!G$48,4,FALSE),F3-D3)) -> 51 | K3: =G3-IFERROR(VLOOKUP($A3,'0501'!$A$1:'0501'!H$44,7,FALSE),IFERROR(VLOOKUP($C3,'0501'!$C$1:'0501'!H$44,5,FALSE),G3-E3)) -> 50 | L3: =IFERROR(K3/J3,) -> 0.98039216
A4: 香椿的功效与作用是什么呢？ | B4: 回答 | C4: 45777 | D4: 78 | E4: 210 | F4: 78 | G4: 210 | H4: =E4/D4 -> 2.6923077 | I4: =G4/F4 -> 2.6923077 | J4: =F4-IFERROR(VLOOKUP($A4,'0501'!$A$1:'0501'!G$48,6,FALSE),IFERROR(VLOOKUP($C4,'0501'!$C$1:'0501'!G$48,4,FALSE),F4-D4)) -> 17 | K4: =G4-IFERROR(VLOOKUP($A4,'0501'!$A$1:'0501'!H$44,7,FALSE),IFERROR(VLOOKUP($C4,'0501'!$C$1:'0501'!H$44,5,FALSE),G4-E4)) -> 45 | L4: =IFERROR(K4/J4,) -> 2.6470588 | M4: 0502顶78,26,10,4，2
A5: 人一天到底要吃多少，才不会太多也不会太少？ | B5: 回答 | C5: 45776 | D5: 445 | E5: 389 | F5: 445 | G5: 389 | H5: =E5/D5 -> 0.8741573 | I5: =G5/F5 -> 0.8741573 | J5: =F5-IFERROR(VLOOKUP($A5,'0501'!$A$1:'0501'!G$48,6,FALSE),IFERROR(VLOOKUP($C5,'0501'!$C$1:'0501'!G$48,4,FALSE),F5-D5)) -> 95 | K5: =G5-IFERROR(VLOOKUP($A5,'0501'!$A$1:'0501'!H$44,7,FALSE),IFERROR(VLOOKUP($C5,'0501'!$C$1:'0501'!H$44,5,FALSE),G5-E5)) -> 21 | L5: =IFERROR(K5/J5,) -> 0.22105263
A6: 同样的时间，为什么早上煮的菜晚上可以吃，但晚上煮的菜第二天早上就叫隔夜菜，吃了就不利于健康呢？ | B6: 回答 | C6: 45775 | D6: 219 | E6: 294 | F6: 219 | G6: 294 | H6: =E6/D6 -> 1.3424658 | I6: =G6/F6 -> 1.3424658 | J6: =F6-IFERROR(VLOOKUP($A6,'0501'!$A$1:'0501'!G$48,6,FALSE),IFERROR(VLOOKUP($C6,'0501'!$C$1:'0501'!G$48,4,FALSE),F6-D6)) -> 19 | K6: =G6-IFERROR(VLOOKUP($A6,'0501'!$A$1:'0501'!H$44,7,FALSE),IFERROR(VLOOKUP($C6,'0501'!$C$1:'0501'!H$44,5,FALSE),G6-E6)) -> 17 | L6: =IFERROR(K6/J6,) -> 0.89473684
A7: 能否告诉我这花团锦簇的是什么树？ | B7: 回答 | C7: 45775 | D7: 135 | E7: 304 | F7: 135 | G7: 304 | H7: =E7/D7 -> 2.2518519 | I7: =G7/F7 -> 2.2518519 | J7: =F7-IFERROR(VLOOKUP($A7,'0501'!$A$1:'0501'!G$48,6,FALSE),IFERROR(VLOOKUP($C7,'0501'!$C$1:'0501'!G$48,4,FALSE),F7-D7)) -> 2 | K7: =G7-IFERROR(VLOOKUP($A7,'0501'!$A$1:'0501'!H$44,7,FALSE),IFERROR(VLOOKUP($C7,'0501'!$C$1:'0501'!H$44,5,FALSE),G7-E7)) -> 0 | L7: =IFERROR(K7/J7,) -> 0
A8: 医生说少油少盐，不可抗拒的原因一直在吃食堂，是不是少吃点多喝汤就达到上述要求？ | B8: 回答 | C8: 45774 | D8: 140 | E8: 216 | F8: 140 | G8: 216 | H8: =E8/D8 -> 1.5428571 | I8: =G8/F8 -> 1.5428571 | J8: =F8-IFERROR(VLOOKUP($A8,'0501'!$A$1:'0501'!G$48,6,FALSE),IFERROR(VLOOKUP($C8,'0501'!$C$1:'0501'!G$48,4,FALSE),F8-D8)) -> 4 | K8: =G8-IFERROR(VLOOKUP($A8,'0501'!$A$1:'0501'!H$44,7,FALSE),IFERROR(VLOOKUP($C8,'0501'!$C$1:'0501'!H$44,5,FALSE),G8-E8)) -> 0 | L8: =IFERROR(K8/J8,) -> 0
A9: 有人说一周吃四个鸡蛋就够了，有人说每天一个鸡蛋最好，到底哪种说法更合适？ | B9: 回答 | C9: 45774 | D9: 385 | E9: 367 | F9: 385 | G9: 367 | H9: =E9/D9 -> 0.95324675 | I9: =G9/F9 -> 0.95324675 | J9: =F9-IFERROR(VLOOKUP($A9,'0501'!$A$1:'0501'!G$48,6,FALSE),IFERROR(VLOOKUP($C9,'0501'!$C$1:'0501'!G$48,4,FALSE),F9-D9)) -> 13 | K9: =G9-IFERROR(VLOOKUP($A9,'0501'!$A$1:'0501'!H$44,7,FALSE),IFERROR(VLOOKUP($C9,'0501'!$C$1:'0501'!H$44,5,FALSE),G9-E9)) -> 4 | L9: =IFERROR(K9/J9,) -> 0.30769231
A10: 这是什么品种的花卉？ | B10: 回答 | C10: 45773 | D10: 138 | E10: 190 | F10: 138 | G10: 190 | H10: =E10/D10 -> 1.3768116 | I10: =G10/F10 -> 1.3768116 | J10: =F10-IFERROR(VLOOKUP($A10,'0501'!$A$1:'0501'!G$48,6,FALSE),IFERROR(VLOOKUP($C10,'0501'!$C$1:'0501'!G$48,4,FALSE),F10-D10)) -> 4 | K10: =G10-IFERROR(VLOOKUP($A10,'0501'!$A$1:'0501'!H$44,7,FALSE),IFERROR(VLOOKUP($C10,'0501'!$C$1:'0501'!H$44,5,FALSE),G10-E10)) -> 0 | L10: =IFERROR(K10/J10,) -> 0
A11: 酸菜炖大骨头好吃的做法有哪些？ | B11: 回答 | C11: 45773 | D11: 217 | E11: 247 | F11: 217 | G11: 247 | H11: =E11/D11 -> 1.1382488 | I11: =G11/F11 -> 1.1382488 | J11: =F11-IFERROR(VLOOKUP($A11,'0501'!$A$1:'0501'!G$48,6,FALSE),IFERROR(VLOOKUP($C11,'0501'!$C$1:'0501'!G$48,4,FALSE),F11-D11)) -> 2 | K11: =G11-IFERROR(VLOOKUP($A11,'0501'!$A$1:'0501'!H$44,7,FALSE),IFERROR(VLOOKUP($C11,'0501'!$C$1:'0501'!H$44,5,FALSE),G11-E11)) -> 6 | L11: =IFERROR(K11/J11,) -> 3
A12: 两杯水中，一杯其中加盐鸡蛋会怎么样？ | B12: 回答 | C12: 45772 | D12: 140 | E12: 519 | F12: 140 | G12: 519 | H12: =E12/D12 -> 3.7071429 | I12: =G12/F12 -> 3.7071429 | J12: =F12-IFERROR(VLOOKUP($A12,'0501'!$A$1:'0501'!G$48,6,FALSE),IFERROR(VLOOKUP($C12,'0501'!$C$1:'0501'!G$48,4,FALSE),F12-D12)) -> 16 | K12: =G12-IFERROR(VLOOKUP($A12,'0501'!$A$1:'0501'!H$44,7,FALSE),IFERROR(VLOOKUP($C12,'0501'!$C$1:'0501'!H$44,5,FALSE),G12-E12)) -> 57 | L12: =IFERROR(K12/J12,) -> 3.5625 | M12: 0430顶99,23,26,2,1
A13: 煎鱼总粘锅破皮是物理问题还是技术问题？家庭厨房如何彻底解决？ | B13: 回答 | C13: 45771 | D13: 155 | E13: 89 | F13: 187 | G13: 183 | H13: =E13/D13 -> 0.57419355 | I13: =G13/F13 -> 0.97860963 | J13: =F13-IFERROR(VLOOKUP($A13,'0501'!$A$1:'0501'!G$48,6,FALSE),IFERROR(VLOOKUP($C13,'0501'!$C$1:'0501'!G$48,4,FALSE),F13-D13)) -> 3 | K13: =G13-IFERROR(VLOOKUP($A13,'0501'!$A$1:'0501'!H$44,7,FALSE),IFERROR(VLOOKUP($C13,'0501'!$C$1:'0501'!H$44,5,FALSE),G13-E13)) -> 6 | L13: =IFERROR(K13/J13,) -> 2
A14: 蝴蝶兰花茎为啥这么粗壮？ | B14: 回答 | C14: 45771 | D14: 78 | E14: 50 | F14: 163 | G14: 121 | H14: =E14/D14 -> 0.64102564 | I14: =G14/F14 -> 0.74233129 | J14: =F14-IFERROR(VLOOKUP($A14,'0501'!$A$1:'0501'!G$48,6,FALSE),IFERROR(VLOOKUP($C14,'0501'!$C$1:'0501'!G$48,4,FALSE),F14-D14)) -> 7 | K14: =G14-IFERROR(VLOOKUP($A14,'0501'!$A$1:'0501'!H$44,7,FALSE),IFERROR(VLOOKUP($C14,'0501'!$C$1:'0501'!H$44,5,FALSE),G14-E14)) -> 0 | L14: =IFERROR(K14/J14,) -> 0
A15: 血压高适合吃哪些食物？ | B15: 回答 | C15: 45770 | D15: 126 | E15: 442 | F15: 213 | G15: 685 | H15: =E15/D15 -> 3.5079365 | I15: =G15/F15 -> 3.2159624 | J15: =F15-IFERROR(VLOOKUP($A15,'0501'!$A$1:'0501'!G$48,6,FALSE),IFERROR(VLOOKUP($C15,'0501'!$C$1:'0501'!G$48,4,FALSE),F15-D15)) -> 3 | K15: =G15-IFERROR(VLOOKUP($A15,'0501'!$A$1:'0501'!H$44,7,FALSE),IFERROR(VLOOKUP($C15,'0501'!$C$1:'0501'!H$44,5,FALSE),G15-E15)) -> 0 | L15: =IFERROR(K15/J15,) -> 0 | M15: 0426顶98,26,40,3,1
A16: 这个长在植物上白色东西是甚么？会不会影响植物生长？ | B16: 回答 | C16: 45769 | D16: 20 | E16: 42 | F16: 142 | G16: 418 | H16: =E16/D16 -> 2.1 | I16: =G16/F16 -> 2.943662 | J16: =F16-IFERROR(VLOOKUP($A16,'0501'!$A$1:'0501'!G$48,6,FALSE),IFERROR(VLOOKUP($C16,'0501'!$C$1:'0501'!G$48,4,FALSE),F16-D16)) -> 1 | K16: =G16-IFERROR(VLOOKUP($A16,'0501'!$A$1:'0501'!H$44,7,FALSE),IFERROR(VLOOKUP($C16,'0501'!$C$1:'0501'!H$44,5,FALSE),G16-E16)) -> 0 | L16: =IFERROR(K16/J16,) -> 0
A17: 你能不能找到一个比较简单的数学问题，但是deepseek却得不到正确结果？ | B17: 回答 | C17: 45769 | D17: 84 | E17: 14 | F17: 550 | G17: 334 | H17: =E17/D17 -> 0.16666667 | I17: =G17/F17 -> 0.60727273 | J17: =F17-IFERROR(VLOOKUP($A17,'0501'!$A$1:'0501'!G$48,6,FALSE),IFERROR(VLOOKUP($C17,'0501'!$C$1:'0501'!G$48,4,FALSE),F17-D17)) -> 4 | K17: =G17-IFERROR(VLOOKUP($A17,'0501'!$A$1:'0501'!H$44,7,FALSE),IFERROR(VLOOKUP($C17,'0501'!$C$1:'0501'!H$44,5,FALSE),G17-E17)) -> 0 | L17: =IFERROR(K17/J17,) -> 0
A18: 同样的电饭煲煮饭，用不同的大米煮，加的水是一样的吗？ | B18: 回答 | C18: 45768 | D18: 20 | E18: 12 | F18: 215 | G18: 603 | H18: =E18/D18 -> 0.6 | I18: =G18/F18 -> 2.8046512 | J18: =F18-IFERROR(VLOOKUP($A18,'0501'!$A$1:'0501'!G$48,6,FALSE),IFERROR(VLOOKUP($C18,'0501'!$C$1:'0501'!G$48,4,FALSE),F18-D18)) -> 0 | K18: =G18-IFERROR(VLOOKUP($A18,'0501'!$A$1:'0501'!H$44,7,FALSE),IFERROR(VLOOKUP($C18,'0501'!$C$1:'0501'!H$44,5,FALSE),G18-E18)) -> 0 | L18: =IFERROR(K18/J18,) -> 0
A19: 怎么分辨桃花樱桃李子树花梨花呢？ | B19: 回答 | C19: 45768 | D19: 40 | E19: 86 | F19: 144 | G19: 469 | H19: =E19/D19 -> 2.15 | I19: =G19/F19 -> 3.2569444 | J19: =F19-IFERROR(VLOOKUP($A19,'0501'!$A$1:'0501'!G$48,6,FALSE),IFERROR(VLOOKUP($C19,'0501'!$C$1:'0501'!G$48,4,FALSE),F19-D19)) -> 2 | K19: =G19-IFERROR(VLOOKUP($A19,'0501'!$A$1:'0501'!H$44,7,FALSE),IFERROR(VLOOKUP($C19,'0501'!$C$1:'0501'!H$44,5,FALSE),G19-E19)) -> 0 | L19: =IFERROR(K19/J19,) -> 0 | M19: 0424顶96,23,30,2,4
A20: 问一个数学问题，可能有99%的人都答错：6个鸡蛋，打碎了两个，煮了两个，吃了两个，还剩几个？ | B20: 回答 | C20: 45766 | D20: 161 | E20: 7 | F20: 883 | G20: 583 | H20: =E20/D20 -> 0.043478261 | I20: =G20/F20 -> 0.66024915 | J20: =F20-IFERROR(VLOOKUP($A20,'0501'!$A$1:'0501'!G$48,6,FALSE),IFERROR(VLOOKUP($C20,'0501'!$C$1:'0501'!G$48,4,FALSE),F20-D20)) -> 34 | K20: =G20-IFERROR(VLOOKUP($A20,'0501'!$A$1:'0501'!H$44,7,FALSE),IFERROR(VLOOKUP($C20,'0501'!$C$1:'0501'!H$44,5,FALSE),G20-E20)) -> 0 | L20: =IFERROR(K20/J20,) -> 0
A21: 为啥大中火煸油 没等油煸出来就糊了? | B21: 回答 | C21: 45765 | D21: 30 | E21: 6 | F21: 401 | G21: 452 | H21: =E21/D21 -> 0.2 | I21: =G21/F21 -> 1.127182 | J21: =F21-IFERROR(VLOOKUP($A21,'0501'!$A$1:'0501'!G$48,6,FALSE),IFERROR(VLOOKUP($C21,'0501'!$C$1:'0501'!G$48,4,FALSE),F21-D21)) -> 0 | K21: =G21-IFERROR(VLOOKUP($A21,'0501'!$A$1:'0501'!H$44,7,FALSE),IFERROR(VLOOKUP($C21,'0501'!$C$1:'0501'!H$44,5,FALSE),G21-E21)) -> 0 | L21: =IFERROR(K21/J21,) -> 0
A22: 一盘饺子姐姐吃剩7个妹妹吃剩9个两人都吃差4个饺子有几个? | B22: 回答 | C22: 45764 | D22: 12 | E22: 7 | F22: 161 | G22: 541 | H22: =E22/D22 -> 0.58333333 | I22: =G22/F22 -> 3.3602484 | J22: =F22-IFERROR(VLOOKUP($A22,'0501'!$A$1:'0501'!G$48,6,FALSE),IFERROR(VLOOKUP($C22,'0501'!$C$1:'0501'!G$48,4,FALSE),F22-D22)) -> 0 | K22: =G22-IFERROR(VLOOKUP($A22,'0501'!$A$1:'0501'!H$44,7,FALSE),IFERROR(VLOOKUP($C22,'0501'!$C$1:'0501'!H$44,5,FALSE),G22-E22)) -> 0 | L22: =IFERROR(K22/J22,) -> 0
A23: 大树被锯掉树冠还能发芽吗？ | B23: 回答 | C23: 45764 | D23: 75 | E23: 7 | F23: 352 | G23: 261 | H23: =E23/D23 -> 0.093333333 | I23: =G23/F23 -> 0.74147727 | J23: =F23-IFERROR(VLOOKUP($A23,'0501'!$A$1:'0501'!G$48,6,FALSE),IFERROR(VLOOKUP($C23,'0501'!$C$1:'0501'!G$48,4,FALSE),F23-D23)) -> 10 | K23: =G23-IFERROR(VLOOKUP($A23,'0501'!$A$1:'0501'!H$44,7,FALSE),IFERROR(VLOOKUP($C23,'0501'!$C$1:'0501'!H$44,5,FALSE),G23-E23)) -> 0 | L23: =IFERROR(K23/J23,) -> 0
A24: 请问怎么能彻底杀死一棵香椿树？ | B24: 回答 | C24: 45763 | D24: 66 | E24: 4 | F24: 649 | G24: 370 | H24: =E24/D24 -> 0.060606061 | I24: =G24/F24 -> 0.57010786 | J24: =F24-IFERROR(VLOOKUP($A24,'0501'!$A$1:'0501'!G$48,6,FALSE),IFERROR(VLOOKUP($C24,'0501'!$C$1:'0501'!G$48,4,FALSE),F24-D24)) -> 1 | K24: =G24-IFERROR(VLOOKUP($A24,'0501'!$A$1:'0501'!H$44,7,FALSE),IFERROR(VLOOKUP($C24,'0501'!$C$1:'0501'!H$44,5,FALSE),G24-E24)) -> 0 | L24: =IFERROR(K24/J24,) -> 0
A25: 少先队员种杨树和柳树共140棵，杨树比柳树多40棵，那么杨树种了多少棵，柳树种了多少棵。? | B25: 回答 | C25: 45763 | D25: 2 | E25: 4 | F25: 130 | G25: 198 | H25: =E25/D25 -> 2 | I25: =G25/F25 -> 1.5230769 | J25: =F25-IFERROR(VLOOKUP($A25,'0501'!$A$1:'0501'!G$48,6,FALSE),IFERROR(VLOOKUP($C25,'0501'!$C$1:'0501'!G$48,4,FALSE),F25-D25)) -> 0 | K25: =G25-IFERROR(VLOOKUP($A25,'0501'!$A$1:'0501'!H$44,7,FALSE),IFERROR(VLOOKUP($C25,'0501'!$C$1:'0501'!H$44,5,FALSE),G25-E25)) -> 0 | L25: =IFERROR(K25/J25,) -> 0 | M25: 0427收益期128，194
A26: 请问在食堂打饭时一两米饭指的是熟重一两还是生重一两? | B26: 回答 | C26: 45762 | D26: 12 | E26: 6 | F26: 595 | G26: 641 | H26: =E26/D26 -> 0.5 | I26: =G26/F26 -> 1.0773109 | J26: =F26-IFERROR(VLOOKUP($A26,'0501'!$A$1:'0501'!G$48,6,FALSE),IFERROR(VLOOKUP($C26,'0501'!$C$1:'0501'!G$48,4,FALSE),F26-D26)) -> 0 | K26: =G26-IFERROR(VLOOKUP($A26,'0501'!$A$1:'0501'!H$44,7,FALSE),IFERROR(VLOOKUP($C26,'0501'!$C$1:'0501'!H$44,5,FALSE),G26-E26)) -> 0 | L26: =IFERROR(K26/J26,) -> 0 | M26: 0428收益期593,635
A27: 做蒸饺时应该怎么和面呢？ | B27: 回答 | C27: 45761 | D27: 27 | E27: 6 | F27: 1055 | G27: 913 | H27: =E27/D27 -> 0.22222222 | I27: =G27/F27 -> 0.86540284 | J27: =F27-IFERROR(VLOOKUP($A27,'0501'!$A$1:'0501'!G$48,6,FALSE),IFERROR(VLOOKUP($C27,'0501'!$C$1:'0501'!G$48,4,FALSE),F27-D27)) -> 1 | K27: =G27-IFERROR(VLOOKUP($A27,'0501'!$A$1:'0501'!H$44,7,FALSE),IFERROR(VLOOKUP($C27,'0501'!$C$1:'0501'!H$44,5,FALSE),G27-E27)) -> 0 | L27: =IFERROR(K27/J27,) -> 0 | M27: 0426收益期1029,907
A28: 为什么我做的红烧肉总是不够软烂入味，有什么小窍门能让红烧肉达到入口即化的口感呢？ | B28: 回答 | C28: 45757 | D28: 12 | E28: 6 | F28: 625 | G28: 763 | H28: =E28/D28 -> 0.5 | I28: =G28/F28 -> 1.2208 | J28: =F28-IFERROR(VLOOKUP($A28,'0501'!$A$1:'0501'!G$48,6,FALSE),IFERROR(VLOOKUP($C28,'0501'!$C$1:'0501'!G$48,4,FALSE),F28-D28)) -> 1 | K28: =G28-IFERROR(VLOOKUP($A28,'0501'!$A$1:'0501'!H$44,7,FALSE),IFERROR(VLOOKUP($C28,'0501'!$C$1:'0501'!H$44,5,FALSE),G28-E28)) -> 0 | L28: =IFERROR(K28/J28,) -> 0 | M28: 0425收益期613,757
A29: 你们采摘过野外的桑葚么？或者采摘过什么野果野菜？口感怎么样？ | B29: 回答 | C29: 45750 | D29: 9 | E29: 12 | F29: 225 | G29: 542 | H29: =E29/D29 -> 1.3333333 | I29: =G29/F29 -> 2.4088889 | J29: =F29-IFERROR(VLOOKUP($A29,'0501'!$A$1:'0501'!G$48,6,FALSE),IFERROR(VLOOKUP($C29,'0501'!$C$1:'0501'!G$48,4,FALSE),F29-D29)) -> 0 | K29: =G29-IFERROR(VLOOKUP($A29,'0501'!$A$1:'0501'!H$44,7,FALSE),IFERROR(VLOOKUP($C29,'0501'!$C$1:'0501'!H$44,5,FALSE),G29-E29)) -> 0 | L29: =IFERROR(K29/J29,) -> 0 | M29: 0426收益期222,530
A30: 钟南山呼吁别再「无效节约」，别让剩饭剩菜伤了胃，剩菜剩饭有哪些危害？生活中还有哪些饮食健康易被忽视？ | B30: 回答 | C30: 45748 | D30: 50 | E30: 13 | F30: 224465 | G30: 10593 | H30: =E30/D30 -> 0.26 | I30: =G30/F30 -> 0.047192213 | J30: =F30-IFERROR(VLOOKUP($A30,'0501'!$A$1:'0501'!G$48,6,FALSE),IFERROR(VLOOKUP($C30,'0501'!$C$1:'0501'!G$48,4,FALSE),F30-D30)) -> 5 | K30: =G30-IFERROR(VLOOKUP($A30,'0501'!$A$1:'0501'!H$44,7,FALSE),IFERROR(VLOOKUP($C30,'0501'!$C$1:'0501'!H$44,5,FALSE),G30-E30)) -> 0 | L30: =IFERROR(K30/J30,) -> 0 | M30: 0407荐22.3万，784,296,399,48
A31: 谁能提供一个猪肉好吃又简单的做法？ | B31: 回答 | C31: 45743 | D31: 86 | E31: 10 | F31: 4885 | G31: 1986 | H31: =E31/D31 -> 0.11627907 | I31: =G31/F31 -> 0.40655067 | J31: =F31-IFERROR(VLOOKUP($A31,'0501'!$A$1:'0501'!G$48,6,FALSE),IFERROR(VLOOKUP($C31,'0501'!$C$1:'0501'!G$48,4,FALSE),F31-D31)) -> 9 | K31: =G31-IFERROR(VLOOKUP($A31,'0501'!$A$1:'0501'!H$44,7,FALSE),IFERROR(VLOOKUP($C31,'0501'!$C$1:'0501'!H$44,5,FALSE),G31-E31)) -> 0 | L31: =IFERROR(K31/J31,) -> 0 | M31: 0425收益期4799,1976
A32: 牛肉水煮40分钟后，轻微炒2分钟，吃起来还是很硬很柴，问题出在哪里呢？ | B32: 回答 | C32: 45741 | D32: 119 | E32: 15 | F32: 1201 | G32: 682 | H32: =E32/D32 -> 0.12605042 | I32: =G32/F32 -> 0.56786012 | J32: =F32-IFERROR(VLOOKUP($A32,'0501'!$A$1:'0501'!G$48,6,FALSE),IFERROR(VLOOKUP($C32,'0501'!$C$1:'0501'!G$48,4,FALSE),F32-D32)) -> 8 | K32: =G32-IFERROR(VLOOKUP($A32,'0501'!$A$1:'0501'!H$44,7,FALSE),IFERROR(VLOOKUP($C32,'0501'!$C$1:'0501'!H$44,5,FALSE),G32-E32)) -> 5 | L32: =IFERROR(K32/J32,) -> 0.625 | M32: 0413收益期928，667
A33: 草莓究竟是哪个季节的果实? | B33: 回答 | C33: 45734 | D33: 40 | E33: 5 | F33: 494 | G33: 670 | H33: =E33/D33 -> 0.125 | I33: =G33/F33 -> 1.3562753 | J33: =F33-IFERROR(VLOOKUP($A33,'0501'!$A$1:'0501'!G$48,6,FALSE),IFERROR(VLOOKUP($C33,'0501'!$C$1:'0501'!G$48,4,FALSE),F33-D33)) -> 6 | K33: =G33-IFERROR(VLOOKUP($A33,'0501'!$A$1:'0501'!H$44,7,FALSE),IFERROR(VLOOKUP($C33,'0501'!$C$1:'0501'!H$44,5,FALSE),G33-E33)) -> 0 | L33: =IFERROR(K33/J33,) -> 0 | M33: 0401收益期317,655
A34: 油炸食物很香，哪些蔬菜适合油炸且非常好吃？ | B34: 回答 | C34: 45719 | D34: 9 | E34: 10 | F34: 379 | G34: 657 | H34: =E34/D34 -> 1.1111111 | I34: =G34/F34 -> 1.7335092 | J34: =F34-IFERROR(VLOOKUP($A34,'0501'!$A$1:'0501'!G$48,6,FALSE),IFERROR(VLOOKUP($C34,'0501'!$C$1:'0501'!G$48,4,FALSE),F34-D34)) -> 2 | K34: =G34-IFERROR(VLOOKUP($A34,'0501'!$A$1:'0501'!H$44,7,FALSE),IFERROR(VLOOKUP($C34,'0501'!$C$1:'0501'!H$44,5,FALSE),G34-E34)) -> 0 | L34: =IFERROR(K34/J34,) -> 0 | M34: 0403收益期359,647
A35: 早餐吃什么最好？是牛奶还是面包？ | B35: 回答 | C35: 45713 | D35: 10 | E35: 31 | F35: 225 | G35: 589 | H35: =E35/D35 -> 3.1 | I35: =G35/F35 -> 2.6177778 | J35: =F35-IFERROR(VLOOKUP($A35,'0501'!$A$1:'0501'!G$48,6,FALSE),IFERROR(VLOOKUP($C35,'0501'!$C$1:'0501'!G$48,4,FALSE),F35-D35)) -> 0 | K35: =G35-IFERROR(VLOOKUP($A35,'0501'!$A$1:'0501'!H$44,7,FALSE),IFERROR(VLOOKUP($C35,'0501'!$C$1:'0501'!H$44,5,FALSE),G35-E35)) -> 0 | L35: =IFERROR(K35/J35,) -> 0 | M35: 0402收益期203,558
A36: 酥脆剂和泡打粉的区别有哪些？ | B36: 回答 | C36: 45691 | D36: 35 | E36: 5 | F36: 319 | G36: 36 | H36: =E36/D36 -> 0.14285714 | I36: =G36/F36 -> 0.11285266 | J36: =F36-IFERROR(VLOOKUP($A36,'0501'!$A$1:'0501'!G$48,6,FALSE),IFERROR(VLOOKUP($C36,'0501'!$C$1:'0501'!G$48,4,FALSE),F36-D36)) -> 2 | K36: =G36-IFERROR(VLOOKUP($A36,'0501'!$A$1:'0501'!H$44,7,FALSE),IFERROR(VLOOKUP($C36,'0501'!$C$1:'0501'!H$44,5,FALSE),G36-E36)) -> 0 | L36: =IFERROR(K36/J36,) -> 0 | M36: 0216收益期91,31
A37: 鸡蛋放两个月没坏还能吃吗？ | B37: 回答 | C37: 45598 | D37: 72 | E37: 2 | F37: 1273 | G37: 789 | H37: =E37/D37 -> 0.027777778 | I37: =G37/F37 -> 0.61979576 | J37: =F37-IFERROR(VLOOKUP($A37,'0501'!$A$1:'0501'!G$48,6,FALSE),IFERROR(VLOOKUP($C37,'0501'!$C$1:'0501'!G$48,4,FALSE),F37-D37)) -> 11 | K37: =G37-IFERROR(VLOOKUP($A37,'0501'!$A$1:'0501'!H$44,7,FALSE),IFERROR(VLOOKUP($C37,'0501'!$C$1:'0501'!H$44,5,FALSE),G37-E37)) -> 0 | L37: =IFERROR(K37/J37,) -> 0 | M37: 0412收益期1091,787
K38: =SUM(K2:K37) -> 337

Sheet 0503
A1: 内容 | B1: 内容类型 | C1: 内容发布时间 | D1: 本期阅读量 | E1: 本期收益 | F1: 累计阅读量 | G1: 累计收益 | J1: 新增浏览 | K1: 新增收益
A2: 自己种的都忘了，请问这个是什么果树? | B2: 回答 | C2: 45779 | D2: 100 | E2: 84 | F2: 100 | G2: 84 | H2: =E2/D2 -> 0.84 | I2: =G2/F2 -> 0.84 | J2: =F2-IFERROR(VLOOKUP($A2,'0502'!$A$1:'0502'!G$48,6,FALSE),IFERROR(VLOOKUP($C2,'0502'!$C$1:'0502'!G$48,4,FALSE),F2-D2)) -> 100 | K2: =G2-IFERROR(VLOOKUP($A2,'0502'!$A$1:'0502'!H$44,7,FALSE),IFERROR(VLOOKUP($C2,'0502'!$C$1:'0502'!H$44,5,FALSE),G2-E2)) -> 84 | L2: =IFERROR(K2/J2,) -> 0.84
A3: 前几天养了四只小鸡，一只死了。还剩三只鸡，其中的一只鸡又被其它两只小鸡把屁眼那块啄的血琳琳，啥原因？ | B3: 回答 | C3: 45778 | D3: 310 | E3: 140 | F3: 310 | G3: 140 | H3: =E3/D3 -> 0.4516129 | I3: =G3/F3 -> 0.4516129 | J3: =F3-IFERROR(VLOOKUP($A3,'0502'!$A$1:'0502'!G$48,6,FALSE),IFERROR(VLOOKUP($C3,'0502'!$C$1:'0502'!G$48,4,FALSE),F3-D3)) -> 28 | K3: =G3-IFERROR(VLOOKUP($A3,'0502'!$A$1:'0502'!H$44,7,FALSE),IFERROR(VLOOKUP($C3,'0502'!$C$1:'0502'!H$44,5,FALSE),G3-E3)) -> 14 | L3: =IFERROR(K3/J3,) -> 0.5
A4: 请问在不破坏树的情况下怎么把树皮腐蚀下来一点，不让大树压到房子? | B4: 回答 | C4: 45777 | D4: 182 | E4: 283 | F4: 182 | G4: 283 | H4: =E4/D4 -> 1.5549451 | I4: =G4/F4 -> 1.5549451 | J4: =F4-IFERROR(VLOOKUP($A4,'0502'!$A$1:'0502'!G$48,6,FALSE),IFERROR(VLOOKUP($C4,'0502'!$C$1:'0502'!G$48,4,FALSE),F4-D4)) -> 39 | K4: =G4-IFERROR(VLOOKUP($A4,'0502'!$A$1:'0502'!H$44,7,FALSE),IFERROR(VLOOKUP($C4,'0502'!$C$1:'0502'!H$44,5,FALSE),G4-E4)) -> 7 | L4: =IFERROR(K4/J4,) -> 0.17948718
A5: 香椿的功效与作用是什么呢？ | B5: 回答 | C5: 45777 | D5: 86 | E5: 222 | F5: 86 | G5: 222 | H5: =E5/D5 -> 2.5813953 | I5: =G5/F5 -> 2.5813953 | J5: =F5-IFERROR(VLOOKUP($A5,'0502'!$A$1:'0502'!G$48,6,FALSE),IFERROR(VLOOKUP($C5,'0502'!$C$1:'0502'!G$48,4,FALSE),F5-D5)) -> 8 | K5: =G5-IFERROR(VLOOKUP($A5,'0502'!$A$1:'0502'!H$44,7,FALSE),IFERROR(VLOOKUP($C5,'0502'!$C$1:'0502'!H$44,5,FALSE),G5-E5)) -> 12 | L5: =IFERROR(K5/J5,) -> 1.5 | M5: 0502顶78,26,10,4，2
A6: 人一天到底要吃多少，才不会太多也不会太少？ | B6: 回答 | C6: 45776 | D6: 516 | E6: 393 | F6: 516 | G6: 393 | H6: =E6/D6 -> 0.76162791 | I6: =G6/F6 -> 0.76162791 | J6: =F6-IFERROR(VLOOKUP($A6,'0502'!$A$1:'0502'!G$48,6,FALSE),IFERROR(VLOOKUP($C6,'0502'!$C$1:'0502'!G$48,4,FALSE),F6-D6)) -> 71 | K6: =G6-IFERROR(VLOOKUP($A6,'0502'!$A$1:'0502'!H$44,7,FALSE),IFERROR(VLOOKUP($C6,'0502'!$C$1:'0502'!H$44,5,FALSE),G6-E6)) -> 4 | L6: =IFERROR(K6/J6,) -> 0.056338028
A7: 同样的时间，为什么早上煮的菜晚上可以吃，但晚上煮的菜第二天早上就叫隔夜菜，吃了就不利于健康呢？ | B7: 回答 | C7: 45775 | D7: 226 | E7: 311 | F7: 226 | G7: 311 | H7: =E7/D7 -> 1.3761062 | I7: =G7/F7 -> 1.3761062 | J7: =F7-IFERROR(VLOOKUP($A7,'0502'!$A$1:'0502'!G$48,6,FALSE),IFERROR(VLOOKUP($C7,'0502'!$C$1:'0502'!G$48,4,FALSE),F7-D7)) -> 7 | K7: =G7-IFERROR(VLOOKUP($A7,'0502'!$A$1:'0502'!H$44,7,FALSE),IFERROR(VLOOKUP($C7,'0502'!$C$1:'0502'!H$44,5,FALSE),G7-E7)) -> 17 | L7: =IFERROR(K7/J7,) -> 2.4285714
A8: 能否告诉我这花团锦簇的是什么树？ | B8: 回答 | C8: 45775 | D8: 136 | E8: 304 | F8: 136 | G8: 304 | H8: =E8/D8 -> 2.2352941 | I8: =G8/F8 -> 2.2352941 | J8: =F8-IFERROR(VLOOKUP($A8,'0502'!$A$1:'0502'!G$48,6,FALSE),IFERROR(VLOOKUP($C8,'0502'!$C$1:'0502'!G$48,4,FALSE),F8-D8)) -> 1 | K8: =G8-IFERROR(VLOOKUP($A8,'0502'!$A$1:'0502'!H$44,7,FALSE),IFERROR(VLOOKUP($C8,'0502'!$C$1:'0502'!H$44,5,FALSE),G8-E8)) -> 0 | L8: =IFERROR(K8/J8,) -> 0
A9: 医生说少油少盐，不可抗拒的原因一直在吃食堂，是不是少吃点多喝汤就达到上述要求？ | B9: 回答 | C9: 45774 | D9: 140 | E9: 216 | F9: 140 | G9: 216 | H9: =E9/D9 -> 1.5428571 | I9: =G9/F9 -> 1.5428571 | J9: =F9-IFERROR(VLOOKUP($A9,'0502'!$A$1:'0502'!G$48,6,FALSE),IFERROR(VLOOKUP($C9,'0502'!$C$1:'0502'!G$48,4,FALSE),F9-D9)) -> 0 | K9: =G9-IFERROR(VLOOKUP($A9,'0502'!$A$1:'0502'!H$44,7,FALSE),IFERROR(VLOOKUP($C9,'0502'!$C$1:'0502'!H$44,5,FALSE),G9-E9)) -> 0 | L9: =IFERROR(K9/J9,) -> 0
A10: 有人说一周吃四个鸡蛋就够了，有人说每天一个鸡蛋最好，到底哪种说法更合适？ | B10: 回答 | C10: 45774 | D10: 388 | E10: 367 | F10: 388 | G10: 367 | H10: =E10/D10 -> 0.94587629 | I10: =G10/F10 -> 0.94587629 | J10: =F10-IFERROR(VLOOKUP($A10,'0502'!$A$1:'0502'!G$48,6,FALSE),IFERROR(VLOOKUP($C10,'0502'!$C$1:'0502'!G$48,4,FALSE),F10-D10)) -> 3 | K10: =G10-IFERROR(VLOOKUP($A10,'0502'!$A$1:'0502'!H$44,7,FALSE),IFERROR(VLOOKUP($C10,'0502'!$C$1:'0502'!H$44,5,FALSE),G10-E10)) -> 0 | L10: =IFERROR(K10/J10,) -> 0
A11: 这是什么品种的花卉？ | B11: 回答 | C11: 45773 | D11: 138 | E11: 190 | F11: 138 | G11: 190 | H11: =E11/D11 -> 1.3768116 | I11: =G11/F11 -> 1.3768116 | J11: =F11-IFERROR(VLOOKUP($A11,'0502'!$A$1:'0502'!G$48,6,FALSE),IFERROR(VLOOKUP($C11,'0502'!$C$1:'0502'!G$48,4,FALSE),F11-D11)) -> 0 | K11: =G11-IFERROR(VLOOKUP($A11,'0502'!$A$1:'0502'!H$44,7,FALSE),IFERROR(VLOOKUP($C11,'0502'!$C$1:'0502'!H$44,5,FALSE),G11-E11)) -> 0 | L11: =IFERROR(K11/J11,) -> 0
A12: 酸菜炖大骨头好吃的做法有哪些？ | B12: 回答 | C12: 45773 | D12: 223 | E12: 247 | F12: 223 | G12: 247 | H12: =E12/D12 -> 1.1076233 | I12: =G12/F12 -> 1.1076233 | J12: =F12-IFERROR(VLOOKUP($A12,'0502'!$A$1:'0502'!G$48,6,FALSE),IFERROR(VLOOKUP($C12,'0502'!$C$1:'0502'!G$48,4,FALSE),F12-D12)) -> 6 | K12: =G12-IFERROR(VLOOKUP($A12,'0502'!$A$1:'0502'!H$44,7,FALSE),IFERROR(VLOOKUP($C12,'0502'!$C$1:'0502'!H$44,5,FALSE),G12-E12)) -> 0 | L12: =IFERROR(K12/J12,) -> 0
A13: 两杯水中，一杯其中加盐鸡蛋会怎么样？ | B13: 回答 | C13: 45772 | D13: 151 | E13: 465 | F13: 197 | G13: 612 | H13: =E13/D13 -> 3.0794702 | I13: =G13/F13 -> 3.106599 | J13: =F13-IFERROR(VLOOKUP($A13,'0502'!$A$1:'0502'!G$48,6,FALSE),IFERROR(VLOOKUP($C13,'0502'!$C$1:'0502'!G$48,4,FALSE),F13-D13)) -> 57 | K13: =G13-IFERROR(VLOOKUP($A13,'0502'!$A$1:'0502'!H$44,7,FALSE),IFERROR(VLOOKUP($C13,'0502'!$C$1:'0502'!H$44,5,FALSE),G13-E13)) -> 93 | L13: =IFERROR(K13/J13,) -> 1.6315789 | M13: 0430顶99,23,26,2,1
A14: 煎鱼总粘锅破皮是物理问题还是技术问题？家庭厨房如何彻底解决？ | B14: 回答 | C14: 45771 | D14: 91 | E14: 18 | F14: 189 | G14: 183 | H14: =E14/D14 -> 0.1978022 | I14: =G14/F14 -> 0.96825397 | J14: =F14-IFERROR(VLOOKUP($A14,'0502'!$A$1:'0502'!G$48,6,FALSE),IFERROR(VLOOKUP($C14,'0502'!$C$1:'0502'!G$48,4,FALSE),F14-D14)) -> 2 | K14: =G14-IFERROR(VLOOKUP($A14,'0502'!$A$1:'0502'!H$44,7,FALSE),IFERROR(VLOOKUP($C14,'0502'!$C$1:'0502'!H$44,5,FALSE),G14-E14)) -> 0 | L14: =IFERROR(K14/J14,) -> 0
A15: 蝴蝶兰花茎为啥这么粗壮？ | B15: 回答 | C15: 45771 | D15: 68 | E15: 20 | F15: 167 | G15: 121 | H15: =E15/D15 -> 0.29411765 | I15: =G15/F15 -> 0.7245509 | J15: =F15-IFERROR(VLOOKUP($A15,'0502'!$A$1:'0502'!G$48,6,FALSE),IFERROR(VLOOKUP($C15,'0502'!$C$1:'0502'!G$48,4,FALSE),F15-D15)) -> 4 | K15: =G15-IFERROR(VLOOKUP($A15,'0502'!$A$1:'0502'!H$44,7,FALSE),IFERROR(VLOOKUP($C15,'0502'!$C$1:'0502'!H$44,5,FALSE),G15-E15)) -> 0 | L15: =IFERROR(K15/J15,) -> 0
A16: 血压高适合吃哪些食物？ | B16: 回答 | C16: 45770 | D16: 121 | E16: 404 | F16: 218 | G16: 685 | H16: =E16/D16 -> 3.338843 | I16: =G16/F16 -> 3.1422018 | J16: =F16-IFERROR(VLOOKUP($A16,'0502'!$A$1:'0502'!G$48,6,FALSE),IFERROR(VLOOKUP($C16,'0502'!$C$1:'0502'!G$48,4,FALSE),F16-D16)) -> 5 | K16: =G16-IFERROR(VLOOKUP($A16,'0502'!$A$1:'0502'!H$44,7,FALSE),IFERROR(VLOOKUP($C16,'0502'!$C$1:'0502'!H$44,5,FALSE),G16-E16)) -> 0 | L16: =IFERROR(K16/J16,) -> 0 | M16: 0426顶98,26,40,3,1
A17: 这个长在植物上白色东西是甚么？会不会影响植物生长？ | B17: 回答 | C17: 45769 | D17: 15 | E17: 35 | F17: 144 | G17: 418 | H17: =E17/D17 -> 2.3333333 | I17: =G17/F17 -> 2.9027778 | J17: =F17-IFERROR(VLOOKUP($A17,'0502'!$A$1:'0502'!G$48,6,FALSE),IFERROR(VLOOKUP($C17,'0502'!$C$1:'0502'!G$48,4,FALSE),F17-D17)) -> 2 | K17: =G17-IFERROR(VLOOKUP($A17,'0502'!$A$1:'0502'!H$44,7,FALSE),IFERROR(VLOOKUP($C17,'0502'!$C$1:'0502'!H$44,5,FALSE),G17-E17)) -> 0 | L17: =IFERROR(K17/J17,) -> 0
A18: 你能不能找到一个比较简单的数学问题，但是deepseek却得不到正确结果？ | B18: 回答 | C18: 45769 | D18: 75 | E18: 14 | F18: 557 | G18: 334 | H18: =E18/D18 -> 0.18666667 | I18: =G18/F18 -> 0.59964093 | J18: =F18-IFERROR(VLOOKUP($A18,'0502'!$A$1:'0502'!G$48,6,FALSE),IFERROR(VLOOKUP($C18,'0502'!$C$1:'0502'!G$48,4,FALSE),F18-D18)) -> 7 | K18: =G18-IFERROR(VLOOKUP($A18,'0502'!$A$1:'0502'!H$44,7,FALSE),IFERROR(VLOOKUP($C18,'0502'!$C$1:'0502'!H$44,5,FALSE),G18-E18)) -> 0 | L18: =IFERROR(K18/J18,) -> 0
A19: 同样的电饭煲煮饭，用不同的大米煮，加的水是一样的吗？ | B19: 回答 | C19: 45768 | D19: 16 | E19: 6 | F19: 216 | G19: 603 | H19: =E19/D19 -> 0.375 | I19: =G19/F19 -> 2.7916667 | J19: =F19-IFERROR(VLOOKUP($A19,'0502'!$A$1:'0502'!G$48,6,FALSE),IFERROR(VLOOKUP($C19,'0502'!$C$1:'0502'!G$48,4,FALSE),F19-D19)) -> 1 | K19: =G19-IFERROR(VLOOKUP($A19,'0502'!$A$1:'0502'!H$44,7,FALSE),IFERROR(VLOOKUP($C19,'0502'!$C$1:'0502'!H$44,5,FALSE),G19-E19)) -> 0 | L19: =IFERROR(K19/J19,) -> 0
A20: 怎么分辨桃花樱桃李子树花梨花呢？ | B20: 回答 | C20: 45768 | D20: 13 | E20: 43 | F20: 144 | G20: 469 | H20: =E20/D20 -> 3.3076923 | I20: =G20/F20 -> 3.2569444 | J20: =F20-IFERROR(VLOOKUP($A20,'0502'!$A$1:'0502'!G$48,6,FALSE),IFERROR(VLOOKUP($C20,'0502'!$C$1:'0502'!G$48,4,FALSE),F20-D20)) -> 0 | K20: =G20-IFERROR(VLOOKUP($A20,'0502'!$A$1:'0502'!H$44,7,FALSE),IFERROR(VLOOKUP($C20,'0502'!$C$1:'0502'!H$44,5,FALSE),G20-E20)) -> 0 | L20: =IFERROR(K20/J20,) -> 0 | M20: 0424顶96,23,30,2,4
A21: 问一个数学问题，可能有99%的人都答错：6个鸡蛋，打碎了两个，煮了两个，吃了两个，还剩几个？ | B21: 回答 | C21: 45766 | D21: 127 | E21: 7 | F21: 885 | G21: 583 | H21: =E21/D21 -> 0.05511811 | I21: =G21/F21 -> 0.65875706 | J21: =F21-IFERROR(VLOOKUP($A21,'0502'!$A$1:'0502'!G$48,6,FALSE),IFERROR(VLOOKUP($C21,'0502'!$C$1:'0502'!G$48,4,FALSE),F21-D21)) -> 2 | K21: =G21-IFERROR(VLOOKUP($A21,'0502'!$A$1:'0502'!H$44,7,FALSE),IFERROR(VLOOKUP($C21,'0502'!$C$1:'0502'!H$44,5,FALSE),G21-E21)) -> 0 | L21: =IFERROR(K21/J21,) -> 0
A22: 为啥大中火煸油 没等油煸出来就糊了? | B22: 回答 | C22: 45765 | D22: 14 | E22: 6 | F22: 401 | G22: 452 | H22: =E22/D22 -> 0.42857143 | I22: =G22/F22 -> 1.127182 | J22: =F22-IFERROR(VLOOKUP($A22,'0502'!$A$1:'0502'!G$48,6,FALSE),IFERROR(VLOOKUP($C22,'0502'!$C$1:'0502'!G$48,4,FALSE),F22-D22)) -> 0 | K22: =G22-IFERROR(VLOOKUP($A22,'0502'!$A$1:'0502'!H$44,7,FALSE),IFERROR(VLOOKUP($C22,'0502'!$C$1:'0502'!H$44,5,FALSE),G22-E22)) -> 0 | L22: =IFERROR(K22/J22,) -> 0
A23: 一盘饺子姐姐吃剩7个妹妹吃剩9个两人都吃差4个饺子有几个? | B23: 回答 | C23: 45764 | D23: 15 | E23: 7 | F23: 164 | G23: 541 | H23: =E23/D23 -> 0.46666667 | I23: =G23/F23 -> 3.2987805 | J23: =F23-IFERROR(VLOOKUP($A23,'0502'!$A$1:'0502'!G$48,6,FALSE),IFERROR(VLOOKUP($C23,'0502'!$C$1:'0502'!G$48,4,FALSE),F23-D23)) -> 3 | K23: =G23-IFERROR(VLOOKUP($A23,'0502'!$A$1:'0502'!H$44,7,FALSE),IFERROR(VLOOKUP($C23,'0502'!$C$1:'0502'!H$44,5,FALSE),G23-E23)) -> 0 | L23: =IFERROR(K23/J23,) -> 0
A24: 大树被锯掉树冠还能发芽吗？ | B24: 回答 | C24: 45764 | D24: 61 | E24: 7 | F24: 356 | G24: 261 | H24: =E24/D24 -> 0.1147541 | I24: =G24/F24 -> 0.73314607 | J24: =F24-IFERROR(VLOOKUP($A24,'0502'!$A$1:'0502'!G$48,6,FALSE),IFERROR(VLOOKUP($C24,'0502'!$C$1:'0502'!G$48,4,FALSE),F24-D24)) -> 4 | K24: =G24-IFERROR(VLOOKUP($A24,'0502'!$A$1:'0502'!H$44,7,FALSE),IFERROR(VLOOKUP($C24,'0502'!$C$1:'0502'!H$44,5,FALSE),G24-E24)) -> 0 | L24: =IFERROR(K24/J24,) -> 0
A25: 请问怎么能彻底杀死一棵香椿树？ | B25: 回答 | C25: 45763 | D25: 68 | E25: 4 | F25: 651 | G25: 370 | H25: =E25/D25 -> 0.058823529 | I25: =G25/F25 -> 0.56835637 | J25: =F25-IFERROR(VLOOKUP($A25,'0502'!$A$1:'0502'!G$48,6,FALSE),IFERROR(VLOOKUP($C25,'0502'!$C$1:'0502'!G$48,4,FALSE),F25-D25)) -> 2 | K25: =G25-IFERROR(VLOOKUP($A25,'0502'!$A$1:'0502'!H$44,7,FALSE),IFERROR(VLOOKUP($C25,'0502'!$C$1:'0502'!H$44,5,FALSE),G25-E25)) -> 0 | L25: =IFERROR(K25/J25,) -> 0
A26: 少先队员种杨树和柳树共140棵，杨树比柳树多40棵，那么杨树种了多少棵，柳树种了多少棵。? | B26: 回答 | C26: 45763 | D26: 2 | E26: 4 | F26: 130 | G26: 198 | H26: =E26/D26 -> 2 | I26: =G26/F26 -> 1.5230769 | J26: =F26-IFERROR(VLOOKUP($A26,'0502'!$A$1:'0502'!G$48,6,FALSE),IFERROR(VLOOKUP($C26,'0502'!$C$1:'0502'!G$48,4,FALSE),F26-D26)) -> 0 | K26: =G26-IFERROR(VLOOKUP($A26,'0502'!$A$1:'0502'!H$44,7,FALSE),IFERROR(VLOOKUP($C26,'0502'!$C$1:'0502'!H$44,5,FALSE),G26-E26)) -> 0 | L26: =IFERROR(K26/J26,) -> 0 | M26: 0427收益期128，194
A27: 请问在食堂打饭时一两米饭指的是熟重一两还是生重一两? | B27: 回答 | C27: 45762 | D27: 7 | E27: 6 | F27: 598 | G27: 641 | H27: =E27/D27 -> 0.85714286 | I27: =G27/F27 -> 1.0719064 | J27: =F27-IFERROR(VLOOKUP($A27,'0502'!$A$1:'0502'!G$48,6,FALSE),IFERROR(VLOOKUP($C27,'0502'!$C$1:'0502'!G$48,4,FALSE),F27-D27)) -> 3 | K27: =G27-IFERROR(VLOOKUP($A27,'0502'!$A$1:'0502'!H$44,7,FALSE),IFERROR(VLOOKUP($C27,'0502'!$C$1:'0502'!H$44,5,FALSE),G27-E27)) -> 0 | L27: =IFERROR(K27/J27,) -> 0 | M27: 0428收益期593,635
A28: 做蒸饺时应该怎么和面呢？ | B28: 回答 | C28: 45761 | D28: 27 | E28: 12 | F28: 1056 | G28: 919 | H28: =E28/D28 -> 0.44444444 | I28: =G28/F28 -> 0.87026515 | J28: =F28-IFERROR(VLOOKUP($A28,'0502'!$A$1:'0502'!G$48,6,FALSE),IFERROR(VLOOKUP($C28,'0502'!$C$1:'0502'!G$48,4,FALSE),F28-D28)) -> 1 | K28: =G28-IFERROR(VLOOKUP($A28,'0502'!$A$1:'0502'!H$44,7,FALSE),IFERROR(VLOOKUP($C28,'0502'!$C$1:'0502'!H$44,5,FALSE),G28-E28)) -> 6 | L28: =IFERROR(K28/J28,) -> 6 | M28: 0426收益期1029,907
A29: 为什么我做的红烧肉总是不够软烂入味，有什么小窍门能让红烧肉达到入口即化的口感呢？ | B29: 回答 | C29: 45757 | D29: 10 | E29: 6 | F29: 626 | G29: 763 | H29: =E29/D29 -> 0.6 | I29: =G29/F29 -> 1.2188498 | J29: =F29-IFERROR(VLOOKUP($A29,'0502'!$A$1:'0502'!G$48,6,FALSE),IFERROR(VLOOKUP($C29,'0502'!$C$1:'0502'!G$48,4,FALSE),F29-D29)) -> 1 | K29: =G29-IFERROR(VLOOKUP($A29,'0502'!$A$1:'0502'!H$44,7,FALSE),IFERROR(VLOOKUP($C29,'0502'!$C$1:'0502'!H$44,5,FALSE),G29-E29)) -> 0 | L29: =IFERROR(K29/J29,) -> 0 | M29: 0425收益期613,757
A30: 你们采摘过野外的桑葚么？或者采摘过什么野果野菜？口感怎么样？ | B30: 回答 | C30: 45750 | D30: 3 | E30: 12 | F30: 225 | G30: 542 | H30: =E30/D30 -> 4 | I30: =G30/F30 -> 2.4088889 | J30: =F30-IFERROR(VLOOKUP($A30,'0502'!$A$1:'0502'!G$48,6,FALSE),IFERROR(VLOOKUP($C30,'0502'!$C$1:'0502'!G$48,4,FALSE),F30-D30)) -> 0 | K30: =G30-IFERROR(VLOOKUP($A30,'0502'!$A$1:'0502'!H$44,7,FALSE),IFERROR(VLOOKUP($C30,'0502'!$C$1:'0502'!H$44,5,FALSE),G30-E30)) -> 0 | L30: =IFERROR(K30/J30,) -> 0 | M30: 0426收益期222,530
A31: 钟南山呼吁别再「无效节约」，别让剩饭剩菜伤了胃，剩菜剩饭有哪些危害？生活中还有哪些饮食健康易被忽视？ | B31: 回答 | C31: 45748 | D31: 51 | E31: 13 | F31: 224470 | G31: 10593 | H31: =E31/D31 -> 0.25490196 | I31: =G31/F31 -> 0.047191161 | J31: =F31-IFERROR(VLOOKUP($A31,'0502'!$A$1:'0502'!G$48,6,FALSE),IFERROR(VLOOKUP($C31,'0502'!$C$1:'0502'!G$48,4,FALSE),F31-D31)) -> 5 | K31: =G31-IFERROR(VLOOKUP($A31,'0502'!$A$1:'0502'!H$44,7,FALSE),IFERROR(VLOOKUP($C31,'0502'!$C$1:'0502'!H$44,5,FALSE),G31-E31)) -> 0 | L31: =IFERROR(K31/J31,) -> 0 | M31: 0407荐22.3万，784,296,399,48
A32: 谁能提供一个猪肉好吃又简单的做法？ | B32: 回答 | C32: 45743 | D32: 68 | E32: 15 | F32: 4893 | G32: 1991 | H32: =E32/D32 -> 0.22058824 | I32: =G32/F32 -> 0.40690783 | J32: =F32-IFERROR(VLOOKUP($A32,'0502'!$A$1:'0502'!G$48,6,FALSE),IFERROR(VLOOKUP($C32,'0502'!$C$1:'0502'!G$48,4,FALSE),F32-D32)) -> 8 | K32: =G32-IFERROR(VLOOKUP($A32,'0502'!$A$1:'0502'!H$44,7,FALSE),IFERROR(VLOOKUP($C32,'0502'!$C$1:'0502'!H$44,5,FALSE),G32-E32)) -> 5 | L32: =IFERROR(K32/J32,) -> 0.625 | M32: 0425收益期4799,1976
A33: 牛肉水煮40分钟后，轻微炒2分钟，吃起来还是很硬很柴，问题出在哪里呢？ | B33: 回答 | C33: 45741 | D33: 109 | E33: 10 | F33: 1213 | G33: 687 | H33: =E33/D33 -> 0.091743119 | I33: =G33/F33 -> 0.56636439 | J33: =F33-IFERROR(VLOOKUP($A33,'0502'!$A$1:'0502'!G$48,6,FALSE),IFERROR(VLOOKUP($C33,'0502'!$C$1:'0502'!G$48,4,FALSE),F33-D33)) -> 12 | K33: =G33-IFERROR(VLOOKUP($A33,'0502'!$A$1:'0502'!H$44,7,FALSE),IFERROR(VLOOKUP($C33,'0502'!$C$1:'0502'!H$44,5,FALSE),G33-E33)) -> 5 | L33: =IFERROR(K33/J33,) -> 0.41666667 | M33: 0413收益期928，667
A34: 草莓究竟是哪个季节的果实? | B34: 回答 | C34: 45734 | D34: 34 | E34: 5 | F34: 494 | G34: 670 | H34: =E34/D34 -> 0.14705882 | I34: =G34/F34 -> 1.3562753 | J34: =F34-IFERROR(VLOOKUP($A34,'0502'!$A$1:'0502'!G$48,6,FALSE),IFERROR(VLOOKUP($C34,'0502'!$C$1:'0502'!G$48,4,FALSE),F34-D34)) -> 0 | K34: =G34-IFERROR(VLOOKUP($A34,'0502'!$A$1:'0502'!H$44,7,FALSE),IFERROR(VLOOKUP($C34,'0502'!$C$1:'0502'!H$44,5,FALSE),G34-E34)) -> 0 | L34: =IFERROR(K34/J34,) -> 0 | M34: 0401收益期317,655
A35: 油炸食物很香，哪些蔬菜适合油炸且非常好吃？ | B35: 回答 | C35: 45719 | D35: 9 | E35: 10 | F35: 379 | G35: 657 | H35: =E35/D35 -> 1.1111111 | I35: =G35/F35 -> 1.7335092 | J35: =F35-IFERROR(VLOOKUP($A35,'0502'!$A$1:'0502'!G$48,6,FALSE),IFERROR(VLOOKUP($C35,'0502'!$C$1:'0502'!G$48,4,FALSE),F35-D35)) -> 0 | K35: =G35-IFERROR(VLOOKUP($A35,'0502'!$A$1:'0502'!H$44,7,FALSE),IFERROR(VLOOKUP($C35,'0502'!$C$1:'0502'!H$44,5,FALSE),G35-E35)) -> 0 | L35: =IFERROR(K35/J35,) -> 0 | M35: 0403收益期359,647
A36: 早餐吃什么最好？是牛奶还是面包？ | B36: 回答 | C36: 45713 | D36: 10 | E36: 31 | F36: 225 | G36: 589 | H36: =E36/D36 -> 3.1 | I36: =G36/F36 -> 2.6177778 | J36: =F36-IFERROR(VLOOKUP($A36,'0502'!$A$1:'0502'!G$48,6,FALSE),IFERROR(VLOOKUP($C36,'0502'!$C$1:'0502'!G$48,4,FALSE),F36-D36)) -> 0 | K36: =G36-IFERROR(VLOOKUP($A36,'0502'!$A$1:'0502'!H$44,7,FALSE),IFERROR(VLOOKUP($C36,'0502'!$C$1:'0502'!H$44,5,FALSE),G36-E36)) -> 0 | L36: =IFERROR(K36/J36,) -> 0 | M36: 0402收益期203,558
A37: 酥脆剂和泡打粉的区别有哪些？ | B37: 回答 | C37: 45691 | D37: 31 | E37: 5 | F37: 321 | G37: 36 | H37: =E37/D37 -> 0.16129032 | I37: =G37/F37 -> 0.11214953 | J37: =F37-IFERROR(VLOOKUP($A37,'0502'!$A$1:'0502'!G$48,6,FALSE),IFERROR(VLOOKUP($C37,'0502'!$C$1:'0502'!G$48,4,FALSE),F37-D37)) -> 2 | K37: =G37-IFERROR(VLOOKUP($A37,'0502'!$A$1:'0502'!H$44,7,FALSE),IFERROR(VLOOKUP($C37,'0502'!$C$1:'0502'!H$44,5,FALSE),G37-E37)) -> 0 | L37: =IFERROR(K37/J37,) -> 0 | M37: 0216收益期91,31
A38: 鸡蛋放两个月没坏还能吃吗？ | B38: 回答 | C38: 45598 | D38: 65 | E38: 2 | F38: 1277 | G38: 789 | H38: =E38/D38 -> 0.030769231 | I38: =G38/F38 -> 0.61785435 | J38: =F38-IFERROR(VLOOKUP($A38,'0502'!$A$1:'0502'!G$48,6,FALSE),IFERROR(VLOOKUP($C38,'0502'!$C$1:'0502'!G$48,4,FALSE),F38-D38)) -> 4 | K38: =G38-IFERROR(VLOOKUP($A38,'0502'!$A$1:'0502'!H$44,7,FALSE),IFERROR(VLOOKUP($C38,'0502'!$C$1:'0502'!H$44,5,FALSE),G38-E38)) -> 0 | L38: =IFERROR(K38/J38,) -> 0 | M38: 0412收益期1091,787
K39: =SUM(K2:K38) -> 247

Sheet 0504
A1: 内容 | B1: 内容类型 | C1: 内容发布时间 | D1: 本期阅读量 | E1: 本期收益 | F1: 累计阅读量 | G1: 累计收益 | J1: 新增浏览 | K1: 新增收益
A2: 明明白面是由小麦制成的，为什么很多老人80年代后才吃得起白面馒头？ | B2: 回答 | C2: 45780 | D2: 508 | E2: 249 | F2: 508 | G2: 249 | H2: =E2/D2 -> 0.49015748 | I2: =G2/F2 -> 0.49015748 | J2: =F2-IFERROR(VLOOKUP($A2,'0503'!$A$1:'0503'!G$48,6,FALSE),IFERROR(VLOOKUP($C2,'0503'!$C$1:'0503'!G$48,4,FALSE),F2-D2)) -> 508 | K2: =G2-IFERROR(VLOOKUP($A2,'0503'!$A$1:'0503'!H$44,7,FALSE),IFERROR(VLOOKUP($C2,'0503'!$C$1:'0503'!H$44,5,FALSE),G2-E2)) -> 249 | L2: =IFERROR(K2/J2,) -> 0.49015748
A3: 自己种的都忘了，请问这个是什么果树? | B3: 回答 | C3: 45779 | D3: 117 | E3: 114 | F3: 117 | G3: 114 | H3: =E3/D3 -> 0.97435897 | I3: =G3/F3 -> 0.97435897 | J3: =F3-IFERROR(VLOOKUP($A3,'0503'!$A$1:'0503'!G$48,6,FALSE),IFERROR(VLOOKUP($C3,'0503'!$C$1:'0503'!G$48,4,FALSE),F3-D3)) -> 17 | K3: =G3-IFERROR(VLOOKUP($A3,'0503'!$A$1:'0503'!H$44,7,FALSE),IFERROR(VLOOKUP($C3,'0503'!$C$1:'0503'!H$44,5,FALSE),G3-E3)) -> 30 | L3: =IFERROR(K3/J3,) -> 1.7647059
A4: 前几天养了四只小鸡，一只死了。还剩三只鸡，其中的一只鸡又被其它两只小鸡把屁眼那块啄的血琳琳，啥原因？ | B4: 回答 | C4: 45778 | D4: 336 | E4: 140 | F4: 336 | G4: 140 | H4: =E4/D4 -> 0.41666667 | I4: =G4/F4 -> 0.41666667 | J4: =F4-IFERROR(VLOOKUP($A4,'0503'!$A$1:'0503'!G$48,6,FALSE),IFERROR(VLOOKUP($C4,'0503'!$C$1:'0503'!G$48,4,FALSE),F4-D4)) -> 26 | K4: =G4-IFERROR(VLOOKUP($A4,'0503'!$A$1:'0503'!H$44,7,FALSE),IFERROR(VLOOKUP($C4,'0503'!$C$1:'0503'!H$44,5,FALSE),G4-E4)) -> 0 | L4: =IFERROR(K4/J4,) -> 0
A5: 请问在不破坏树的情况下怎么把树皮腐蚀下来一点，不让大树压到房子? | B5: 回答 | C5: 45777 | D5: 189 | E5: 283 | F5: 189 | G5: 283 | H5: =E5/D5 -> 1.4973545 | I5: =G5/F5 -> 1.4973545 | J5: =F5-IFERROR(VLOOKUP($A5,'0503'!$A$1:'0503'!G$48,6,FALSE),IFERROR(VLOOKUP($C5,'0503'!$C$1:'0503'!G$48,4,FALSE),F5-D5)) -> 7 | K5: =G5-IFERROR(VLOOKUP($A5,'0503'!$A$1:'0503'!H$44,7,FALSE),IFERROR(VLOOKUP($C5,'0503'!$C$1:'0503'!H$44,5,FALSE),G5-E5)) -> 0 | L5: =IFERROR(K5/J5,) -> 0
A6: 香椿的功效与作用是什么呢？ | B6: 回答 | C6: 45777 | D6: 92 | E6: 260 | F6: 92 | G6: 260 | H6: =E6/D6 -> 2.826087 | I6: =G6/F6 -> 2.826087 | J6: =F6-IFERROR(VLOOKUP($A6,'0503'!$A$1:'0503'!G$48,6,FALSE),IFERROR(VLOOKUP($C6,'0503'!$C$1:'0503'!G$48,4,FALSE),F6-D6)) -> 6 | K6: =G6-IFERROR(VLOOKUP($A6,'0503'!$A$1:'0503'!H$44,7,FALSE),IFERROR(VLOOKUP($C6,'0503'!$C$1:'0503'!H$44,5,FALSE),G6-E6)) -> 38 | L6: =IFERROR(K6/J6,) -> 6.3333333 | M6: 0502顶78,26,10,4，2
A7: 人一天到底要吃多少，才不会太多也不会太少？ | B7: 回答 | C7: 45776 | D7: 563 | E7: 393 | F7: 563 | G7: 393 | H7: =E7/D7 -> 0.69804618 | I7: =G7/F7 -> 0.69804618 | J7: =F7-IFERROR(VLOOKUP($A7,'0503'!$A$1:'0503'!G$48,6,FALSE),IFERROR(VLOOKUP($C7,'0503'!$C$1:'0503'!G$48,4,FALSE),F7-D7)) -> 47 | K7: =G7-IFERROR(VLOOKUP($A7,'0503'!$A$1:'0503'!H$44,7,FALSE),IFERROR(VLOOKUP($C7,'0503'!$C$1:'0503'!H$44,5,FALSE),G7-E7)) -> 0 | L7: =IFERROR(K7/J7,) -> 0
A8: 同样的时间，为什么早上煮的菜晚上可以吃，但晚上煮的菜第二天早上就叫隔夜菜，吃了就不利于健康呢？ | B8: 回答 | C8: 45775 | D8: 232 | E8: 311 | F8: 232 | G8: 311 | H8: =E8/D8 -> 1.3405172 | I8: =G8/F8 -> 1.3405172 | J8: =F8-IFERROR(VLOOKUP($A8,'0503'!$A$1:'0503'!G$48,6,FALSE),IFERROR(VLOOKUP($C8,'0503'!$C$1:'0503'!G$48,4,FALSE),F8-D8)) -> 6 | K8: =G8-IFERROR(VLOOKUP($A8,'0503'!$A$1:'0503'!H$44,7,FALSE),IFERROR(VLOOKUP($C8,'0503'!$C$1:'0503'!H$44,5,FALSE),G8-E8)) -> 0 | L8: =IFERROR(K8/J8,) -> 0
A9: 能否告诉我这花团锦簇的是什么树？ | B9: 回答 | C9: 45775 | D9: 136 | E9: 304 | F9: 136 | G9: 304 | H9: =E9/D9 -> 2.2352941 | I9: =G9/F9 -> 2.2352941 | J9: =F9-IFERROR(VLOOKUP($A9,'0503'!$A$1:'0503'!G$48,6,FALSE),IFERROR(VLOOKUP($C9,'0503'!$C$1:'0503'!G$48,4,FALSE),F9-D9)) -> 0 | K9: =G9-IFERROR(VLOOKUP($A9,'0503'!$A$1:'0503'!H$44,7,FALSE),IFERROR(VLOOKUP($C9,'0503'!$C$1:'0503'!H$44,5,FALSE),G9-E9)) -> 0 | L9: =IFERROR(K9/J9,) -> 0
A10: 医生说少油少盐，不可抗拒的原因一直在吃食堂，是不是少吃点多喝汤就达到上述要求？ | B10: 回答 | C10: 45774 | D10: 140 | E10: 216 | F10: 140 | G10: 216 | H10: =E10/D10 -> 1.5428571 | I10: =G10/F10 -> 1.5428571 | J10: =F10-IFERROR(VLOOKUP($A10,'0503'!$A$1:'0503'!G$48,6,FALSE),IFERROR(VLOOKUP($C10,'0503'!$C$1:'0503'!G$48,4,FALSE),F10-D10)) -> 0 | K10: =G10-IFERROR(VLOOKUP($A10,'0503'!$A$1:'0503'!H$44,7,FALSE),IFERROR(VLOOKUP($C10,'0503'!$C$1:'0503'!H$44,5,FALSE),G10-E10)) -> 0 | L10: =IFERROR(K10/J10,) -> 0
A11: 有人说一周吃四个鸡蛋就够了，有人说每天一个鸡蛋最好，到底哪种说法更合适？ | B11: 回答 | C11: 45774 | D11: 390 | E11: 367 | F11: 390 | G11: 367 | H11: =E11/D11 -> 0.94102564 | I11: =G11/F11 -> 0.94102564 | J11: =F11-IFERROR(VLOOKUP($A11,'0503'!$A$1:'0503'!G$48,6,FALSE),IFERROR(VLOOKUP($C11,'0503'!$C$1:'0503'!G$48,4,FALSE),F11-D11)) -> 2 | K11: =G11-IFERROR(VLOOKUP($A11,'0503'!$A$1:'0503'!H$44,7,FALSE),IFERROR(VLOOKUP($C11,'0503'!$C$1:'0503'!H$44,5,FALSE),G11-E11)) -> 0 | L11: =IFERROR(K11/J11,) -> 0
A12: 这是什么品种的花卉？ | B12: 回答 | C12: 45773 | D12: 83 | E12: 37 | F12: 142 | G12: 190 | H12: =E12/D12 -> 0.44578313 | I12: =G12/F12 -> 1.3380282 | J12: =F12-IFERROR(VLOOKUP($A12,'0503'!$A$1:'0503'!G$48,6,FALSE),IFERROR(VLOOKUP($C12,'0503'!$C$1:'0503'!G$48,4,FALSE),F12-D12)) -> 4 | K12: =G12-IFERROR(VLOOKUP($A12,'0503'!$A$1:'0503'!H$44,7,FALSE),IFERROR(VLOOKUP($C12,'0503'!$C$1:'0503'!H$44,5,FALSE),G12-E12)) -> 0 | L12: =IFERROR(K12/J12,) -> 0
A13: 酸菜炖大骨头好吃的做法有哪些？ | B13: 回答 | C13: 45773 | D13: 142 | E13: 69 | F13: 223 | G13: 247 | H13: =E13/D13 -> 0.48591549 | I13: =G13/F13 -> 1.1076233 | J13: =F13-IFERROR(VLOOKUP($A13,'0503'!$A$1:'0503'!G$48,6,FALSE),IFERROR(VLOOKUP($C13,'0503'!$C$1:'0503'!G$48,4,FALSE),F13-D13)) -> 0 | K13: =G13-IFERROR(VLOOKUP($A13,'0503'!$A$1:'0503'!H$44,7,FALSE),IFERROR(VLOOKUP($C13,'0503'!$C$1:'0503'!H$44,5,FALSE),G13-E13)) -> 0 | L13: =IFERROR(K13/J13,) -> 0
A14: 两杯水中，一杯其中加盐鸡蛋会怎么样？ | B14: 回答 | C14: 45772 | D14: 117 | E14: 293 | F14: 198 | G14: 612 | H14: =E14/D14 -> 2.5042735 | I14: =G14/F14 -> 3.0909091 | J14: =F14-IFERROR(VLOOKUP($A14,'0503'!$A$1:'0503'!G$48,6,FALSE),IFERROR(VLOOKUP($C14,'0503'!$C$1:'0503'!G$48,4,FALSE),F14-D14)) -> 1 | K14: =G14-IFERROR(VLOOKUP($A14,'0503'!$A$1:'0503'!H$44,7,FALSE),IFERROR(VLOOKUP($C14,'0503'!$C$1:'0503'!H$44,5,FALSE),G14-E14)) -> 0 | L14: =IFERROR(K14/J14,) -> 0 | M14: 0430顶99,23,26,2,1
A15: 煎鱼总粘锅破皮是物理问题还是技术问题？家庭厨房如何彻底解决？ | B15: 回答 | C15: 45771 | D15: 67 | E15: 18 | F15: 189 | G15: 183 | H15: =E15/D15 -> 0.26865672 | I15: =G15/F15 -> 0.96825397 | J15: =F15-IFERROR(VLOOKUP($A15,'0503'!$A$1:'0503'!G$48,6,FALSE),IFERROR(VLOOKUP($C15,'0503'!$C$1:'0503'!G$48,4,FALSE),F15-D15)) -> 0 | K15: =G15-IFERROR(VLOOKUP($A15,'0503'!$A$1:'0503'!H$44,7,FALSE),IFERROR(VLOOKUP($C15,'0503'!$C$1:'0503'!H$44,5,FALSE),G15-E15)) -> 0 | L15: =IFERROR(K15/J15,) -> 0
A16: 蝴蝶兰花茎为啥这么粗壮？ | B16: 回答 | C16: 45771 | D16: 64 | E16: 12 | F16: 172 | G16: 121 | H16: =E16/D16 -> 0.1875 | I16: =G16/F16 -> 0.70348837 | J16: =F16-IFERROR(VLOOKUP($A16,'0503'!$A$1:'0503'!G$48,6,FALSE),IFERROR(VLOOKUP($C16,'0503'!$C$1:'0503'!G$48,4,FALSE),F16-D16)) -> 5 | K16: =G16-IFERROR(VLOOKUP($A16,'0503'!$A$1:'0503'!H$44,7,FALSE),IFERROR(VLOOKUP($C16,'0503'!$C$1:'0503'!H$44,5,FALSE),G16-E16)) -> 0 | L16: =IFERROR(K16/J16,) -> 0
A17: 血压高适合吃哪些食物？ | B17: 回答 | C17: 45770 | D17: 100 | E17: 240 | F17: 224 | G17: 685 | H17: =E17/D17 -> 2.4 | I17: =G17/F17 -> 3.0580357 | J17: =F17-IFERROR(VLOOKUP($A17,'0503'!$A$1:'0503'!G$48,6,FALSE),IFERROR(VLOOKUP($C17,'0503'!$C$1:'0503'!G$48,4,FALSE),F17-D17)) -> 6 | K17: =G17-IFERROR(VLOOKUP($A17,'0503'!$A$1:'0503'!H$44,7,FALSE),IFERROR(VLOOKUP($C17,'0503'!$C$1:'0503'!H$44,5,FALSE),G17-E17)) -> 0 | L17: =IFERROR(K17/J17,) -> 0 | M17: 0426顶98,26,40,3,1
A18: 这个长在植物上白色东西是甚么？会不会影响植物生长？ | B18: 回答 | C18: 45769 | D18: 13 | E18: 7 | F18: 145 | G18: 418 | H18: =E18/D18 -> 0.53846154 | I18: =G18/F18 -> 2.8827586 | J18: =F18-IFERROR(VLOOKUP($A18,'0503'!$A$1:'0503'!G$48,6,FALSE),IFERROR(VLOOKUP($C18,'0503'!$C$1:'0503'!G$48,4,FALSE),F18-D18)) -> 1 | K18: =G18-IFERROR(VLOOKUP($A18,'0503'!$A$1:'0503'!H$44,7,FALSE),IFERROR(VLOOKUP($C18,'0503'!$C$1:'0503'!H$44,5,FALSE),G18-E18)) -> 0 | L18: =IFERROR(K18/J18,) -> 0
A19: 同样的电饭煲煮饭，用不同的大米煮，加的水是一样的吗？ | B19: 回答 | C19: 45768 | D19: 10 | E19: 6 | F19: 216 | G19: 603 | H19: =E19/D19 -> 0.6 | I19: =G19/F19 -> 2.7916667 | J19: =F19-IFERROR(VLOOKUP($A19,'0503'!$A$1:'0503'!G$48,6,FALSE),IFERROR(VLOOKUP($C19,'0503'!$C$1:'0503'!G$48,4,FALSE),F19-D19)) -> 0 | K19: =G19-IFERROR(VLOOKUP($A19,'0503'!$A$1:'0503'!H$44,7,FALSE),IFERROR(VLOOKUP($C19,'0503'!$C$1:'0503'!H$44,5,FALSE),G19-E19)) -> 0 | L19: =IFERROR(K19/J19,) -> 0
A20: 为啥大中火煸油 没等油煸出来就糊了? | B20: 回答 | C20: 45765 | D20: 6 | E20: 6 | F20: 401 | G20: 452 | H20: =E20/D20 -> 1 | I20: =G20/F20 -> 1.127182 | J20: =F20-IFERROR(VLOOKUP($A20,'0503'!$A$1:'0503'!G$48,6,FALSE),IFERROR(VLOOKUP($C20,'0503'!$C$1:'0503'!G$48,4,FALSE),F20-D20)) -> 0 | K20: =G20-IFERROR(VLOOKUP($A20,'0503'!$A$1:'0503'!H$44,7,FALSE),IFERROR(VLOOKUP($C20,'0503'!$C$1:'0503'!H$44,5,FALSE),G20-E20)) -> 0 | L20: =IFERROR(K20/J20,) -> 0
A21: 一盘饺子姐姐吃剩7个妹妹吃剩9个两人都吃差4个饺子有几个? | B21: 回答 | C21: 45764 | D21: 15 | E21: 7 | F21: 164 | G21: 541 | H21: =E21/D21 -> 0.46666667 | I21: =G21/F21 -> 3.2987805 | J21: =F21-IFERROR(VLOOKUP($A21,'0503'!$A$1:'0503'!G$48,6,FALSE),IFERROR(VLOOKUP($C21,'0503'!$C$1:'0503'!G$48,4,FALSE),F21-D21)) -> 0 | K21: =G21-IFERROR(VLOOKUP($A21,'0503'!$A$1:'0503'!H$44,7,FALSE),IFERROR(VLOOKUP($C21,'0503'!$C$1:'0503'!H$44,5,FALSE),G21-E21)) -> 0 | L21: =IFERROR(K21/J21,) -> 0
A22: 大树被锯掉树冠还能发芽吗？ | B22: 回答 | C22: 45764 | D22: 57 | E22: 21 | F22: 364 | G22: 275 | H22: =E22/D22 -> 0.36842105 | I22: =G22/F22 -> 0.75549451 | J22: =F22-IFERROR(VLOOKUP($A22,'0503'!$A$1:'0503'!G$48,6,FALSE),IFERROR(VLOOKUP($C22,'0503'!$C$1:'0503'!G$48,4,FALSE),F22-D22)) -> 8 | K22: =G22-IFERROR(VLOOKUP($A22,'0503'!$A$1:'0503'!H$44,7,FALSE),IFERROR(VLOOKUP($C22,'0503'!$C$1:'0503'!H$44,5,FALSE),G22-E22)) -> 14 | L22: =IFERROR(K22/J22,) -> 1.75
A23: 少先队员种杨树和柳树共140棵，杨树比柳树多40棵，那么杨树种了多少棵，柳树种了多少棵。? | B23: 回答 | C23: 45763 | D23: 2 | E23: 4 | F23: 130 | G23: 198 | H23: =E23/D23 -> 2 | I23: =G23/F23 -> 1.5230769 | J23: =F23-IFERROR(VLOOKUP($A23,'0503'!$A$1:'0503'!G$48,6,FALSE),IFERROR(VLOOKUP($C23,'0503'!$C$1:'0503'!G$48,4,FALSE),F23-D23)) -> 0 | K23: =G23-IFERROR(VLOOKUP($A23,'0503'!$A$1:'0503'!H$44,7,FALSE),IFERROR(VLOOKUP($C23,'0503'!$C$1:'0503'!H$44,5,FALSE),G23-E23)) -> 0 | L23: =IFERROR(K23/J23,) -> 0 | M23: 0427收益期128，194
A24: 请问在食堂打饭时一两米饭指的是熟重一两还是生重一两? | B24: 回答 | C24: 45762 | D24: 9 | E24: 6 | F24: 600 | G24: 641 | H24: =E24/D24 -> 0.66666667 | I24: =G24/F24 -> 1.0683333 | J24: =F24-IFERROR(VLOOKUP($A24,'0503'!$A$1:'0503'!G$48,6,FALSE),IFERROR(VLOOKUP($C24,'0503'!$C$1:'0503'!G$48,4,FALSE),F24-D24)) -> 2 | K24: =G24-IFERROR(VLOOKUP($A24,'0503'!$A$1:'0503'!H$44,7,FALSE),IFERROR(VLOOKUP($C24,'0503'!$C$1:'0503'!H$44,5,FALSE),G24-E24)) -> 0 | L24: =IFERROR(K24/J24,) -> 0 | M24: 0428收益期593,635
A25: 做蒸饺时应该怎么和面呢？ | B25: 回答 | C25: 45761 | D25: 27 | E25: 12 | F25: 1056 | G25: 919 | H25: =E25/D25 -> 0.44444444 | I25: =G25/F25 -> 0.87026515 | J25: =F25-IFERROR(VLOOKUP($A25,'0503'!$A$1:'0503'!G$48,6,FALSE),IFERROR(VLOOKUP($C25,'0503'!$C$1:'0503'!G$48,4,FALSE),F25-D25)) -> 0 | K25: =G25-IFERROR(VLOOKUP($A25,'0503'!$A$1:'0503'!H$44,7,FALSE),IFERROR(VLOOKUP($C25,'0503'!$C$1:'0503'!H$44,5,FALSE),G25-E25)) -> 0 | L25: =IFERROR(K25/J25,) -> 0 | M25: 0426收益期1029,907
A26: 为什么我做的红烧肉总是不够软烂入味，有什么小窍门能让红烧肉达到入口即化的口感呢？ | B26: 回答 | C26: 45757 | D26: 10 | E26: 6 | F26: 626 | G26: 763 | H26: =E26/D26 -> 0.6 | I26: =G26/F26 -> 1.2188498 | J26: =F26-IFERROR(VLOOKUP($A26,'0503'!$A$1:'0503'!G$48,6,FALSE),IFERROR(VLOOKUP($C26,'0503'!$C$1:'0503'!G$48,4,FALSE),F26-D26)) -> 0 | K26: =G26-IFERROR(VLOOKUP($A26,'0503'!$A$1:'0503'!H$44,7,FALSE),IFERROR(VLOOKUP($C26,'0503'!$C$1:'0503'!H$44,5,FALSE),G26-E26)) -> 0 | L26: =IFERROR(K26/J26,) -> 0 | M26: 0425收益期613,757
A27: 家里吃剩的煮鸡蛋，可以用来做花肥吗？ | B27: 回答 | C27: 45751 | D27: 15 | E27: 8 | F27: 161 | G27: 266 | H27: =E27/D27 -> 0.53333333 | I27: =G27/F27 -> 1.6521739 | J27: =F27-IFERROR(VLOOKUP($A27,'0503'!$A$1:'0503'!G$48,6,FALSE),IFERROR(VLOOKUP($C27,'0503'!$C$1:'0503'!G$48,4,FALSE),F27-D27)) -> 15 | K27: =G27-IFERROR(VLOOKUP($A27,'0503'!$A$1:'0503'!H$44,7,FALSE),IFERROR(VLOOKUP($C27,'0503'!$C$1:'0503'!H$44,5,FALSE),G27-E27)) -> 8 | L27: =IFERROR(K27/J27,) -> 0.53333333 | M27: 0421收益期134,258
A28: 你们采摘过野外的桑葚么？或者采摘过什么野果野菜？口感怎么样？ | B28: 回答 | C28: 45750 | D28: 3 | E28: 12 | F28: 225 | G28: 542 | H28: =E28/D28 -> 4 | I28: =G28/F28 -> 2.4088889 | J28: =F28-IFERROR(VLOOKUP($A28,'0503'!$A$1:'0503'!G$48,6,FALSE),IFERROR(VLOOKUP($C28,'0503'!$C$1:'0503'!G$48,4,FALSE),F28-D28)) -> 0 | K28: =G28-IFERROR(VLOOKUP($A28,'0503'!$A$1:'0503'!H$44,7,FALSE),IFERROR(VLOOKUP($C28,'0503'!$C$1:'0503'!H$44,5,FALSE),G28-E28)) -> 0 | L28: =IFERROR(K28/J28,) -> 0 | M28: 0426收益期222,530
A29: 钟南山呼吁别再「无效节约」，别让剩饭剩菜伤了胃，剩菜剩饭有哪些危害？生活中还有哪些饮食健康易被忽视？ | B29: 回答 | C29: 45748 | D29: 45 | E29: 13 | F29: 224472 | G29: 10593 | H29: =E29/D29 -> 0.28888889 | I29: =G29/F29 -> 0.047190741 | J29: =F29-IFERROR(VLOOKUP($A29,'0503'!$A$1:'0503'!G$48,6,FALSE),IFERROR(VLOOKUP($C29,'0503'!$C$1:'0503'!G$48,4,FALSE),F29-D29)) -> 2 | K29: =G29-IFERROR(VLOOKUP($A29,'0503'!$A$1:'0503'!H$44,7,FALSE),IFERROR(VLOOKUP($C29,'0503'!$C$1:'0503'!H$44,5,FALSE),G29-E29)) -> 0 | L29: =IFERROR(K29/J29,) -> 0 | M29: 0407荐22.3万，784,296,399,48
A30: 谁能提供一个猪肉好吃又简单的做法？ | B30: 回答 | C30: 45743 | D30: 64 | E30: 15 | F30: 4897 | G30: 1991 | H30: =E30/D30 -> 0.234375 | I30: =G30/F30 -> 0.40657545 | J30: =F30-IFERROR(VLOOKUP($A30,'0503'!$A$1:'0503'!G$48,6,FALSE),IFERROR(VLOOKUP($C30,'0503'!$C$1:'0503'!G$48,4,FALSE),F30-D30)) -> 4 | K30: =G30-IFERROR(VLOOKUP($A30,'0503'!$A$1:'0503'!H$44,7,FALSE),IFERROR(VLOOKUP($C30,'0503'!$C$1:'0503'!H$44,5,FALSE),G30-E30)) -> 0 | L30: =IFERROR(K30/J30,) -> 0 | M30: 0425收益期4799,1976
A31: 牛肉水煮40分钟后，轻微炒2分钟，吃起来还是很硬很柴，问题出在哪里呢？ | B31: 回答 | C31: 45741 | D31: 111 | E31: 10 | F31: 1224 | G31: 687 | H31: =E31/D31 -> 0.09009009 | I31: =G31/F31 -> 0.56127451 | J31: =F31-IFERROR(VLOOKUP($A31,'0503'!$A$1:'0503'!G$48,6,FALSE),IFERROR(VLOOKUP($C31,'0503'!$C$1:'0503'!G$48,4,FALSE),F31-D31)) -> 11 | K31: =G31-IFERROR(VLOOKUP($A31,'0503'!$A$1:'0503'!H$44,7,FALSE),IFERROR(VLOOKUP($C31,'0503'!$C$1:'0503'!H$44,5,FALSE),G31-E31)) -> 0 | L31: =IFERROR(K31/J31,) -> 0 | M31: 0413收益期928，667
A32: 油炸食物很香，哪些蔬菜适合油炸且非常好吃？ | B32: 回答 | C32: 45719 | D32: 8 | E32: 10 | F32: 379 | G32: 657 | H32: =E32/D32 -> 1.25 | I32: =G32/F32 -> 1.7335092 | J32: =F32-IFERROR(VLOOKUP($A32,'0503'!$A$1:'0503'!G$48,6,FALSE),IFERROR(VLOOKUP($C32,'0503'!$C$1:'0503'!G$48,4,FALSE),F32-D32)) -> 0 | K32: =G32-IFERROR(VLOOKUP($A32,'0503'!$A$1:'0503'!H$44,7,FALSE),IFERROR(VLOOKUP($C32,'0503'!$C$1:'0503'!H$44,5,FALSE),G32-E32)) -> 0 | L32: =IFERROR(K32/J32,) -> 0 | M32: 0403收益期359,647
A33: 早餐吃什么最好？是牛奶还是面包？ | B33: 回答 | C33: 45713 | D33: 6 | E33: 31 | F33: 226 | G33: 589 | H33: =E33/D33 -> 5.1666667 | I33: =G33/F33 -> 2.6061947 | J33: =F33-IFERROR(VLOOKUP($A33,'0503'!$A$1:'0503'!G$48,6,FALSE),IFERROR(VLOOKUP($C33,'0503'!$C$1:'0503'!G$48,4,FALSE),F33-D33)) -> 1 | K33: =G33-IFERROR(VLOOKUP($A33,'0503'!$A$1:'0503'!H$44,7,FALSE),IFERROR(VLOOKUP($C33,'0503'!$C$1:'0503'!H$44,5,FALSE),G33-E33)) -> 0 | L33: =IFERROR(K33/J33,) -> 0 | M33: 0402收益期203,558
A34: 酥脆剂和泡打粉的区别有哪些？ | B34: 回答 | C34: 45691 | D34: 28 | E34: 5 | F34: 321 | G34: 36 | H34: =E34/D34 -> 0.17857143 | I34: =G34/F34 -> 0.11214953 | J34: =F34-IFERROR(VLOOKUP($A34,'0503'!$A$1:'0503'!G$48,6,FALSE),IFERROR(VLOOKUP($C34,'0503'!$C$1:'0503'!G$48,4,FALSE),F34-D34)) -> 0 | K34: =G34-IFERROR(VLOOKUP($A34,'0503'!$A$1:'0503'!H$44,7,FALSE),IFERROR(VLOOKUP($C34,'0503'!$C$1:'0503'!H$44,5,FALSE),G34-E34)) -> 0 | L34: =IFERROR(K34/J34,) -> 0 | M34: 0216收益期91,31
K35: =SUM(K2:K34) -> 339

Sheet 0505
A1: 内容 | B1: 内容类型 | C1: 内容发布时间 | D1: 本期阅读量 | E1: 本期收益 | F1: 累计阅读量 | G1: 累计收益 | J1: 新增浏览 | K1: 新增收益
A2: 有人见过路边这种果实么？ | B2: 回答 | C2: 45781 | D2: 73 | E2: 210 | F2: 73 | G2: 210 | H2: =E2/D2 -> 2.8767123 | I2: =G2/F2 -> 2.8767123 | J2: =F2-IFERROR(VLOOKUP($A2,'0504'!$A$1:'0504'!G$48,6,FALSE),IFERROR(VLOOKUP($C2,'0504'!$C$1:'0504'!G$48,4,FALSE),F2-D2)) -> 73 | K2: =G2-IFERROR(VLOOKUP($A2,'0504'!$A$1:'0504'!H$44,7,FALSE),IFERROR(VLOOKUP($C2,'0504'!$C$1:'0504'!H$44,5,FALSE),G2-E2)) -> 210 | L2: =IFERROR(K2/J2,) -> 2.8767123
A3: 明明白面是由小麦制成的，为什么很多老人80年代后才吃得起白面馒头？ | B3: 回答 | C3: 45780 | D3: 701 | E3: 404 | F3: 701 | G3: 404 | H3: =E3/D3 -> 0.57631954 | I3: =G3/F3 -> 0.57631954 | J3: =F3-IFERROR(VLOOKUP($A3,'0504'!$A$1:'0504'!G$48,6,FALSE),IFERROR(VLOOKUP($C3,'0504'!$C$1:'0504'!G$48,4,FALSE),F3-D3)) -> 193 | K3: =G3-IFERROR(VLOOKUP($A3,'0504'!$A$1:'0504'!H$44,7,FALSE),IFERROR(VLOOKUP($C3,'0504'!$C$1:'0504'!H$44,5,FALSE),G3-E3)) -> 155 | L3: =IFERROR(K3/J3,) -> 0.80310881
A4: 自己种的都忘了，请问这个是什么果树? | B4: 回答 | C4: 45779 | D4: 133 | E4: 139 | F4: 133 | G4: 139 | H4: =E4/D4 -> 1.0451128 | I4: =G4/F4 -> 1.0451128 | J4: =F4-IFERROR(VLOOKUP($A4,'0504'!$A$1:'0504'!G$48,6,FALSE),IFERROR(VLOOKUP($C4,'0504'!$C$1:'0504'!G$48,4,FALSE),F4-D4)) -> 16 | K4: =G4-IFERROR(VLOOKUP($A4,'0504'!$A$1:'0504'!H$44,7,FALSE),IFERROR(VLOOKUP($C4,'0504'!$C$1:'0504'!H$44,5,FALSE),G4-E4)) -> 25 | L4: =IFERROR(K4/J4,) -> 1.5625
A5: 前几天养了四只小鸡，一只死了。还剩三只鸡，其中的一只鸡又被其它两只小鸡把屁眼那块啄的血琳琳，啥原因？ | B5: 回答 | C5: 45778 | D5: 342 | E5: 154 | F5: 342 | G5: 154 | H5: =E5/D5 -> 0.4502924 | I5: =G5/F5 -> 0.4502924 | J5: =F5-IFERROR(VLOOKUP($A5,'0504'!$A$1:'0504'!G$48,6,FALSE),IFERROR(VLOOKUP($C5,'0504'!$C$1:'0504'!G$48,4,FALSE),F5-D5)) -> 6 | K5: =G5-IFERROR(VLOOKUP($A5,'0504'!$A$1:'0504'!H$44,7,FALSE),IFERROR(VLOOKUP($C5,'0504'!$C$1:'0504'!H$44,5,FALSE),G5-E5)) -> 14 | L5: =IFERROR(K5/J5,) -> 2.3333333
